{"timestamp": "2025-10-15 11:05:11", "level": "ERROR", "logger": "src.db.database", "message": "Database initialization failed: 'AsyncEngine' object has no attribute '_run_ddl_visitor'", "taskName": "Task-2", "asctime": "2025-10-15 11:05:11,957"}
{"timestamp": "2025-10-15 11:05:11", "level": "ERROR", "logger": "src.main", "message": "Application startup failed: 'AsyncEngine' object has no attribute '_run_ddl_visitor'", "taskName": "Task-2", "asctime": "2025-10-15 11:05:11,957"}
{"timestamp": "2025-10-15 11:05:17", "level": "ERROR", "logger": "src.db.database", "message": "Database initialization failed: 'AsyncEngine' object has no attribute '_run_ddl_visitor'", "taskName": "Task-2", "asctime": "2025-10-15 11:05:17,258"}
{"timestamp": "2025-10-15 11:05:17", "level": "ERROR", "logger": "src.main", "message": "Application startup failed: 'AsyncEngine' object has no attribute '_run_ddl_visitor'", "taskName": "Task-2", "asctime": "2025-10-15 11:05:17,259"}
{"timestamp": "2025-10-15 11:05:22", "level": "ERROR", "logger": "src.db.database", "message": "Database initialization failed: 'AsyncEngine' object has no attribute '_run_ddl_visitor'", "taskName": "Task-2", "asctime": "2025-10-15 11:05:22,933"}
{"timestamp": "2025-10-15 11:05:22", "level": "ERROR", "logger": "src.main", "message": "Application startup failed: 'AsyncEngine' object has no attribute '_run_ddl_visitor'", "taskName": "Task-2", "asctime": "2025-10-15 11:05:22,933"}
{"timestamp": "2025-10-15 11:05:29", "level": "ERROR", "logger": "src.db.database", "message": "Database initialization failed: 'AsyncEngine' object has no attribute '_run_ddl_visitor'", "taskName": "Task-2", "asctime": "2025-10-15 11:05:29,111"}
{"timestamp": "2025-10-15 11:05:29", "level": "ERROR", "logger": "src.main", "message": "Application startup failed: 'AsyncEngine' object has no attribute '_run_ddl_visitor'", "taskName": "Task-2", "asctime": "2025-10-15 11:05:29,112"}
{"timestamp": "2025-10-15 11:05:36", "level": "ERROR", "logger": "src.db.database", "message": "Database initialization failed: 'AsyncEngine' object has no attribute '_run_ddl_visitor'", "taskName": "Task-2", "asctime": "2025-10-15 11:05:36,005"}
{"timestamp": "2025-10-15 11:05:36", "level": "ERROR", "logger": "src.main", "message": "Application startup failed: 'AsyncEngine' object has no attribute '_run_ddl_visitor'", "taskName": "Task-2", "asctime": "2025-10-15 11:05:36,006"}
{"timestamp": "2025-10-15 11:05:43", "level": "ERROR", "logger": "src.db.database", "message": "Database initialization failed: 'AsyncEngine' object has no attribute '_run_ddl_visitor'", "taskName": "Task-2", "asctime": "2025-10-15 11:05:43,211"}
{"timestamp": "2025-10-15 11:05:43", "level": "ERROR", "logger": "src.main", "message": "Application startup failed: 'AsyncEngine' object has no attribute '_run_ddl_visitor'", "taskName": "Task-2", "asctime": "2025-10-15 11:05:43,212"}
{"timestamp": "2025-10-15 11:05:52", "level": "ERROR", "logger": "src.db.database", "message": "Database initialization failed: 'AsyncEngine' object has no attribute '_run_ddl_visitor'", "taskName": "Task-2", "asctime": "2025-10-15 11:05:52,510"}
{"timestamp": "2025-10-15 11:05:52", "level": "ERROR", "logger": "src.main", "message": "Application startup failed: 'AsyncEngine' object has no attribute '_run_ddl_visitor'", "taskName": "Task-2", "asctime": "2025-10-15 11:05:52,510"}
{"timestamp": "2025-10-15 11:06:05", "level": "ERROR", "logger": "src.db.database", "message": "Database initialization failed: 'AsyncEngine' object has no attribute '_run_ddl_visitor'", "taskName": "Task-2", "asctime": "2025-10-15 11:06:05,045"}
{"timestamp": "2025-10-15 11:06:05", "level": "ERROR", "logger": "src.main", "message": "Application startup failed: 'AsyncEngine' object has no attribute '_run_ddl_visitor'", "taskName": "Task-2", "asctime": "2025-10-15 11:06:05,046"}
{"timestamp": "2025-10-15 11:06:15", "level": "ERROR", "logger": "src.db.database", "message": "Database initialization failed: '_GeneratorContextManager' object does not support the asynchronous context manager protocol", "taskName": "Task-2", "asctime": "2025-10-15 11:06:15,939"}
{"timestamp": "2025-10-15 11:06:15", "level": "ERROR", "logger": "src.main", "message": "Application startup failed: '_GeneratorContextManager' object does not support the asynchronous context manager protocol", "taskName": "Task-2", "asctime": "2025-10-15 11:06:15,940"}
{"timestamp": "2025-10-15 11:06:22", "level": "ERROR", "logger": "src.db.database", "message": "Database initialization failed: '_GeneratorContextManager' object does not support the asynchronous context manager protocol", "taskName": "Task-2", "asctime": "2025-10-15 11:06:22,305"}
{"timestamp": "2025-10-15 11:06:22", "level": "ERROR", "logger": "src.main", "message": "Application startup failed: '_GeneratorContextManager' object does not support the asynchronous context manager protocol", "taskName": "Task-2", "asctime": "2025-10-15 11:06:22,305"}
{"timestamp": "2025-10-15 11:06:29", "level": "ERROR", "logger": "src.db.database", "message": "Database initialization failed: '_GeneratorContextManager' object does not support the asynchronous context manager protocol", "taskName": "Task-2", "asctime": "2025-10-15 11:06:29,013"}
{"timestamp": "2025-10-15 11:06:29", "level": "ERROR", "logger": "src.main", "message": "Application startup failed: '_GeneratorContextManager' object does not support the asynchronous context manager protocol", "taskName": "Task-2", "asctime": "2025-10-15 11:06:29,014"}
{"timestamp": "2025-10-15 11:06:35", "level": "ERROR", "logger": "src.db.database", "message": "Database initialization failed: '_GeneratorContextManager' object does not support the asynchronous context manager protocol", "taskName": "Task-2", "asctime": "2025-10-15 11:06:35,114"}
{"timestamp": "2025-10-15 11:06:35", "level": "ERROR", "logger": "src.main", "message": "Application startup failed: '_GeneratorContextManager' object does not support the asynchronous context manager protocol", "taskName": "Task-2", "asctime": "2025-10-15 11:06:35,114"}
{"timestamp": "2025-10-15 11:06:42", "level": "ERROR", "logger": "src.db.database", "message": "Database initialization failed: '_GeneratorContextManager' object does not support the asynchronous context manager protocol", "taskName": "Task-2", "asctime": "2025-10-15 11:06:42,669"}
{"timestamp": "2025-10-15 11:06:42", "level": "ERROR", "logger": "src.main", "message": "Application startup failed: '_GeneratorContextManager' object does not support the asynchronous context manager protocol", "taskName": "Task-2", "asctime": "2025-10-15 11:06:42,669"}
{"timestamp": "2025-10-15 11:06:50", "level": "ERROR", "logger": "src.db.database", "message": "Database initialization failed: object Row can't be used in 'await' expression", "taskName": "Task-2", "asctime": "2025-10-15 11:06:50,367"}
{"timestamp": "2025-10-15 11:06:50", "level": "ERROR", "logger": "src.main", "message": "Application startup failed: object Row can't be used in 'await' expression", "taskName": "Task-2", "asctime": "2025-10-15 11:06:50,367"}
{"timestamp": "2025-10-15 11:06:58", "level": "ERROR", "logger": "src.db.database", "message": "Database initialization failed: object Row can't be used in 'await' expression", "taskName": "Task-2", "asctime": "2025-10-15 11:06:58,439"}
{"timestamp": "2025-10-15 11:06:58", "level": "ERROR", "logger": "src.main", "message": "Application startup failed: object Row can't be used in 'await' expression", "taskName": "Task-2", "asctime": "2025-10-15 11:06:58,440"}
{"timestamp": "2025-10-15 11:07:04", "level": "ERROR", "logger": "src.db.database", "message": "Database initialization failed: object Row can't be used in 'await' expression", "taskName": "Task-2", "asctime": "2025-10-15 11:07:04,165"}
{"timestamp": "2025-10-15 11:07:04", "level": "ERROR", "logger": "src.main", "message": "Application startup failed: object Row can't be used in 'await' expression", "taskName": "Task-2", "asctime": "2025-10-15 11:07:04,166"}
{"timestamp": "2025-10-15 11:07:09", "level": "ERROR", "logger": "src.db.database", "message": "Database initialization failed: object Row can't be used in 'await' expression", "taskName": "Task-2", "asctime": "2025-10-15 11:07:09,797"}
{"timestamp": "2025-10-15 11:07:09", "level": "ERROR", "logger": "src.main", "message": "Application startup failed: object Row can't be used in 'await' expression", "taskName": "Task-2", "asctime": "2025-10-15 11:07:09,798"}
{"timestamp": "2025-10-15 11:07:15", "level": "ERROR", "logger": "src.db.database", "message": "Database initialization failed: object Row can't be used in 'await' expression", "taskName": "Task-2", "asctime": "2025-10-15 11:07:15,671"}
{"timestamp": "2025-10-15 11:07:15", "level": "ERROR", "logger": "src.main", "message": "Application startup failed: object Row can't be used in 'await' expression", "taskName": "Task-2", "asctime": "2025-10-15 11:07:15,671"}
{"timestamp": "2025-10-15 11:07:22", "level": "ERROR", "logger": "src.db.database", "message": "Database initialization failed: object Row can't be used in 'await' expression", "taskName": "Task-2", "asctime": "2025-10-15 11:07:22,419"}
{"timestamp": "2025-10-15 11:07:22", "level": "ERROR", "logger": "src.main", "message": "Application startup failed: object Row can't be used in 'await' expression", "taskName": "Task-2", "asctime": "2025-10-15 11:07:22,420"}
{"timestamp": "2025-10-15 11:07:30", "level": "ERROR", "logger": "src.db.database", "message": "Database initialization failed: object Row can't be used in 'await' expression", "taskName": "Task-2", "asctime": "2025-10-15 11:07:30,482"}
{"timestamp": "2025-10-15 11:07:30", "level": "ERROR", "logger": "src.main", "message": "Application startup failed: object Row can't be used in 'await' expression", "taskName": "Task-2", "asctime": "2025-10-15 11:07:30,482"}
{"timestamp": "2025-10-15 11:07:39", "level": "ERROR", "logger": "src.main", "message": "Application startup failed: Database health check failed: '_GeneratorContextManager' object does not support the asynchronous context manager protocol", "taskName": "Task-2", "asctime": "2025-10-15 11:07:39,828"}
{"timestamp": "2025-10-15 11:07:46", "level": "ERROR", "logger": "src.main", "message": "Application startup failed: Database health check failed: '_GeneratorContextManager' object does not support the asynchronous context manager protocol", "taskName": "Task-2", "asctime": "2025-10-15 11:07:46,913"}
{"timestamp": "2025-10-15 11:07:52", "level": "ERROR", "logger": "src.main", "message": "Application startup failed: Database health check failed: '_GeneratorContextManager' object does not support the asynchronous context manager protocol", "taskName": "Task-2", "asctime": "2025-10-15 11:07:52,997"}
{"timestamp": "2025-10-15 11:07:59", "level": "ERROR", "logger": "src.main", "message": "Application startup failed: Database health check failed: '_GeneratorContextManager' object does not support the asynchronous context manager protocol", "taskName": "Task-2", "asctime": "2025-10-15 11:07:59,608"}
{"timestamp": "2025-10-15 11:08:06", "level": "ERROR", "logger": "src.main", "message": "Application startup failed: Database health check failed: '_GeneratorContextManager' object does not support the asynchronous context manager protocol", "taskName": "Task-2", "asctime": "2025-10-15 11:08:06,130"}
{"timestamp": "2025-10-15 11:08:13", "level": "ERROR", "logger": "src.main", "message": "Application startup failed: Database health check failed: '_GeneratorContextManager' object does not support the asynchronous context manager protocol", "taskName": "Task-2", "asctime": "2025-10-15 11:08:13,067"}
{"timestamp": "2025-10-15 11:08:20", "level": "ERROR", "logger": "src.main", "message": "Application startup failed: '_GeneratorContextManager' object does not support the asynchronous context manager protocol", "taskName": "Task-2", "asctime": "2025-10-15 11:08:20,594"}
{"timestamp": "2025-10-15 11:08:29", "level": "ERROR", "logger": "src.main", "message": "Application startup failed: '_GeneratorContextManager' object does not support the asynchronous context manager protocol", "taskName": "Task-2", "asctime": "2025-10-15 11:08:29,864"}
{"timestamp": "2025-10-15 11:08:36", "level": "ERROR", "logger": "src.main", "message": "Application startup failed: '_GeneratorContextManager' object does not support the asynchronous context manager protocol", "taskName": "Task-2", "asctime": "2025-10-15 11:08:36,906"}
{"timestamp": "2025-10-15 11:08:42", "level": "ERROR", "logger": "src.main", "message": "Application startup failed: '_GeneratorContextManager' object does not support the asynchronous context manager protocol", "taskName": "Task-2", "asctime": "2025-10-15 11:08:42,909"}
{"timestamp": "2025-10-15 11:08:49", "level": "ERROR", "logger": "src.main", "message": "Application startup failed: '_GeneratorContextManager' object does not support the asynchronous context manager protocol", "taskName": "Task-2", "asctime": "2025-10-15 11:08:49,395"}
{"timestamp": "2025-10-15 11:08:55", "level": "ERROR", "logger": "src.main", "message": "Application startup failed: '_GeneratorContextManager' object does not support the asynchronous context manager protocol", "taskName": "Task-2", "asctime": "2025-10-15 11:08:55,325"}
{"timestamp": "2025-10-15 11:09:01", "level": "ERROR", "logger": "src.main", "message": "Application startup failed: '_GeneratorContextManager' object does not support the asynchronous context manager protocol", "taskName": "Task-2", "asctime": "2025-10-15 11:09:01,845"}
{"timestamp": "2025-10-15 11:09:08", "level": "ERROR", "logger": "src.main", "message": "Application startup failed: '_GeneratorContextManager' object does not support the asynchronous context manager protocol", "taskName": "Task-2", "asctime": "2025-10-15 11:09:08,678"}
{"timestamp": "2025-10-15 11:09:17", "level": "ERROR", "logger": "src.main", "message": "Application startup failed: '_GeneratorContextManager' object does not support the asynchronous context manager protocol", "taskName": "Task-2", "asctime": "2025-10-15 11:09:17,147"}
{"timestamp": "2025-10-15 11:09:29", "level": "ERROR", "logger": "src.main", "message": "Application startup failed: '_GeneratorContextManager' object does not support the asynchronous context manager protocol", "taskName": "Task-2", "asctime": "2025-10-15 11:09:29,164"}
{"timestamp": "2025-10-15 11:09:47", "level": "ERROR", "logger": "src.main", "message": "Application startup failed: '_GeneratorContextManager' object does not support the asynchronous context manager protocol", "taskName": "Task-2", "asctime": "2025-10-15 11:09:47,780"}
{"timestamp": "2025-10-15 11:10:19", "level": "ERROR", "logger": "src.main", "message": "Application startup failed: name 'Decimal' is not defined", "taskName": "Task-2", "asctime": "2025-10-15 11:10:19,507"}
{"timestamp": "2025-10-15 11:10:51", "level": "ERROR", "logger": "src.main", "message": "Failed to initialize position monitoring worker: '_GeneratorContextManager' object is not an iterator", "taskName": "Task-2", "asctime": "2025-10-15 11:10:51,617"}
{"timestamp": "2025-10-15 11:19:00", "level": "ERROR", "logger": "src.main", "message": "Failed to initialize position monitoring worker: '_GeneratorContextManager' object is not an iterator", "taskName": "Task-2", "asctime": "2025-10-15 11:19:00,004"}
{"timestamp": "2025-10-15 11:26:58", "level": "ERROR", "logger": "src.main", "message": "Failed to initialize position monitoring worker: '_GeneratorContextManager' object is not an iterator", "taskName": "Task-2", "asctime": "2025-10-15 11:26:58,707"}
{"timestamp": "2025-10-15 11:30:54", "level": "ERROR", "logger": "src.main", "message": "Failed to initialize position monitoring worker: '_GeneratorContextManager' object is not an iterator", "taskName": "Task-2", "asctime": "2025-10-15 11:30:54,042"}
{"timestamp": "2025-10-15 12:10:10", "level": "ERROR", "logger": "src.main", "message": "Failed to initialize position monitoring worker: '_GeneratorContextManager' object is not an iterator", "taskName": "Task-2", "asctime": "2025-10-15 12:10:10,109"}
{"timestamp": "2025-10-15 12:16:15", "level": "ERROR", "logger": "src.main", "message": "Failed to initialize position monitoring worker: '_GeneratorContextManager' object is not an iterator", "taskName": "Task-2", "asctime": "2025-10-15 12:16:15,310"}
{"timestamp": "2025-10-15 12:20:51", "level": "ERROR", "logger": "src.main", "message": "Failed to initialize position monitoring worker: '_GeneratorContextManager' object is not an iterator", "taskName": "Task-2", "asctime": "2025-10-15 12:20:51,354"}
{"timestamp": "2025-10-15 12:25:54", "level": "ERROR", "logger": "src.main", "message": "Failed to initialize position monitoring worker: '_GeneratorContextManager' object is not an iterator", "taskName": "Task-2", "asctime": "2025-10-15 12:25:54,331"}
{"timestamp": "2025-10-15 12:28:00", "level": "ERROR", "logger": "src.main", "message": "Failed to initialize position monitoring worker: '_GeneratorContextManager' object is not an iterator", "taskName": "Task-2", "asctime": "2025-10-15 12:28:00,072"}
{"timestamp": "2025-10-15 12:31:52", "level": "ERROR", "logger": "src.main", "message": "Failed to initialize position monitoring worker: '_GeneratorContextManager' object is not an iterator", "taskName": "Task-2", "asctime": "2025-10-15 12:31:52,118"}
{"timestamp": "2025-10-15 12:34:32", "level": "ERROR", "logger": "src.main", "message": "Failed to initialize position monitoring worker: '_GeneratorContextManager' object is not an iterator", "taskName": "Task-2", "asctime": "2025-10-15 12:34:32,682"}
{"timestamp": "2025-10-15 12:36:05", "level": "ERROR", "logger": "src.main", "message": "Failed to initialize position monitoring worker: '_GeneratorContextManager' object is not an iterator", "taskName": "Task-2", "asctime": "2025-10-15 12:36:05,893"}
{"timestamp": "2025-10-15 12:38:14", "level": "ERROR", "logger": "src.main", "message": "Failed to initialize position monitoring worker: '_GeneratorContextManager' object is not an iterator", "taskName": "Task-2", "asctime": "2025-10-15 12:38:14,406"}
{"timestamp": "2025-10-15 12:40:13", "level": "ERROR", "logger": "src.main", "message": "Failed to initialize position monitoring worker: '_GeneratorContextManager' object is not an iterator", "taskName": "Task-2", "asctime": "2025-10-15 12:40:13,907"}
{"timestamp": "2025-10-16 19:36:19", "level": "ERROR", "logger": "src.main", "message": "Failed to initialize position monitoring worker: '_GeneratorContextManager' object is not an iterator", "taskName": "Task-2", "asctime": "2025-10-16 19:36:19,658"}
{"timestamp": "2025-10-16 19:40:50", "level": "ERROR", "logger": "src.main", "message": "Failed to initialize position monitoring worker: '_GeneratorContextManager' object is not an iterator", "taskName": "Task-2", "asctime": "2025-10-16 19:40:50,541"}
{"timestamp": "2025-10-16 19:53:10", "level": "ERROR", "logger": "src.main", "message": "Failed to initialize position monitoring worker: '_GeneratorContextManager' object is not an iterator", "taskName": "Task-2", "asctime": "2025-10-16 19:53:10,830"}
{"timestamp": "2025-10-16 19:55:41", "level": "ERROR", "logger": "src.main", "message": "Failed to initialize position monitoring worker: '_GeneratorContextManager' object is not an iterator", "taskName": "Task-2", "asctime": "2025-10-16 19:55:41,007"}
{"timestamp": "2025-10-16 19:58:10", "level": "ERROR", "logger": "src.main", "message": "Failed to initialize position monitoring worker: '_GeneratorContextManager' object is not an iterator", "taskName": "Task-2", "asctime": "2025-10-16 19:58:10,602"}
{"timestamp": "2025-10-16 20:01:37", "level": "ERROR", "logger": "src.main", "message": "Failed to initialize position monitoring worker: '_GeneratorContextManager' object is not an iterator", "taskName": "Task-2", "asctime": "2025-10-16 20:01:37,339"}
{"timestamp": "2025-10-16 20:04:54", "level": "ERROR", "logger": "src.main", "message": "Failed to initialize position monitoring worker: '_GeneratorContextManager' object is not an iterator", "taskName": "Task-2", "asctime": "2025-10-16 20:04:54,324"}
{"timestamp": "2025-10-16 20:07:23", "level": "ERROR", "logger": "src.main", "message": "Failed to initialize position monitoring worker: '_GeneratorContextManager' object is not an iterator", "taskName": "Task-2", "asctime": "2025-10-16 20:07:23,949"}
{"timestamp": "2025-10-16 20:09:18", "level": "ERROR", "logger": "src.main", "message": "Failed to initialize position monitoring worker: '_GeneratorContextManager' object is not an iterator", "taskName": "Task-2", "asctime": "2025-10-16 20:09:18,116"}
{"timestamp": "2025-10-16 20:12:35", "level": "ERROR", "logger": "src.main", "message": "Failed to initialize position monitoring worker: '_GeneratorContextManager' object is not an iterator", "taskName": "Task-2", "asctime": "2025-10-16 20:12:35,757"}
{"timestamp": "2025-10-16 20:14:35", "level": "ERROR", "logger": "src.main", "message": "Failed to initialize position monitoring worker: '_GeneratorContextManager' object is not an iterator", "taskName": "Task-2", "asctime": "2025-10-16 20:14:35,303"}
{"timestamp": "2025-10-16 20:22:29", "level": "ERROR", "logger": "src.main", "message": "Failed to initialize position monitoring worker: '_GeneratorContextManager' object is not an iterator", "taskName": "Task-2", "asctime": "2025-10-16 20:22:29,711"}
{"timestamp": "2025-10-16 20:25:58", "level": "ERROR", "logger": "src.main", "message": "Failed to initialize position monitoring worker: '_GeneratorContextManager' object is not an iterator", "taskName": "Task-2", "asctime": "2025-10-16 20:25:58,540"}
{"timestamp": "2025-10-16 20:31:11", "level": "ERROR", "logger": "src.main", "message": "Failed to initialize position monitoring worker: '_GeneratorContextManager' object is not an iterator", "taskName": "Task-2", "asctime": "2025-10-16 20:31:11,342"}
{"timestamp": "2025-10-16 20:43:24", "level": "ERROR", "logger": "src.main", "message": "Failed to initialize position monitoring worker: '_GeneratorContextManager' object is not an iterator", "taskName": "Task-2", "asctime": "2025-10-16 20:43:24,533"}
{"timestamp": "2025-10-16 20:44:42", "level": "ERROR", "logger": "src.db.database", "message": "Failed to update user: (sqlalchemy.dialects.postgresql.asyncpg.Error) <class 'asyncpg.exceptions.StringDataRightTruncationError'>: value too long for type character varying(100)\n[SQL: UPDATE users SET encrypted_telegram_token=$1::VARCHAR, encrypted_telegram_chat_id=$2::VARCHAR WHERE users.wallet_address = $3::VARCHAR]\n[parameters: ('Z0FBQUFBQm84Vms2OHFuZlNtQWswWHVTaG03MDhxNGJhMWlKNm5fR2w2aUsySzZUcVdaaEwtNm1kbnh4dEtyQmhPa3dQbnNaRHVDWDAxRzU3a29yTFI0VTQzb0pCNmUwclN5RExSb1p3V3lyR2UyY0V2TGhJOTdUZldMUjhLTXcxbDlfX1pZYldkUUg=', 'Z0FBQUFBQm84Vms2anJPOGhDbHNkeUIzeHlCanZ0TnBMd3NjZDV2UmR4aTVHejY3U01DV1I5TDhKcHB6S3VONk5PUGkydDZyTHRZYUZibnltU1VQR25mcHV4c0xyaDZYQnc9PQ==', '0xfe09335d5d71431fef3d53beddc772c8269bf953')]\n(Background on this error at: https://sqlalche.me/e/20/dbapi)", "taskName": "starlette.middleware.base.BaseHTTPMiddleware.__call__.<locals>.call_next.<locals>.coro", "asctime": "2025-10-16 20:44:42,201"}
{"timestamp": "2025-10-16 20:47:07", "level": "ERROR", "logger": "src.main", "message": "Failed to initialize position monitoring worker: '_GeneratorContextManager' object is not an iterator", "taskName": "Task-2", "asctime": "2025-10-16 20:47:07,370"}
{"timestamp": "2025-10-16 21:40:24", "level": "ERROR", "logger": "src.main", "message": "Failed to initialize position monitoring worker: '_GeneratorContextManager' object is not an iterator", "taskName": "Task-2", "asctime": "2025-10-16 21:40:24,110"}
{"timestamp": "2025-10-16 21:40:41", "level": "ERROR", "logger": "src.bot.dydx_client", "message": "Failed to create dYdX client: The use of the Mnemonic features of Account is disabled by default until its API stabilizes. To use these features, please enable them by running `Account.enable_unaudited_hdwallet_features()` and try again.", "taskName": "starlette.middleware.base.BaseHTTPMiddleware.__call__.<locals>.call_next.<locals>.coro", "asctime": "2025-10-16 21:40:41,549"}
{"timestamp": "2025-10-16 21:40:41", "level": "ERROR", "logger": "src.main", "message": "Unhandled exception: name 'logger' is not defined", "exception": "Traceback (most recent call last):\n  File \"/usr/local/lib/python3.12/site-packages/anyio/streams/memory.py\", line 98, in receive\n    return self.receive_nowait()\n           ^^^^^^^^^^^^^^^^^^^^^\n  File \"/usr/local/lib/python3.12/site-packages/anyio/streams/memory.py\", line 93, in receive_nowait\n    raise WouldBlock\nanyio.WouldBlock\n\nDuring handling of the above exception, another exception occurred:\n\nTraceback (most recent call last):\n  File \"/usr/local/lib/python3.12/site-packages/starlette/middleware/base.py\", line 78, in call_next\n    message = await recv_stream.receive()\n              ^^^^^^^^^^^^^^^^^^^^^^^^^^^\n  File \"/usr/local/lib/python3.12/site-packages/anyio/streams/memory.py\", line 118, in receive\n    raise EndOfStream\nanyio.EndOfStream\n\nDuring handling of the above exception, another exception occurred:\n\nTraceback (most recent call last):\n  File \"/usr/local/lib/python3.12/site-packages/starlette/middleware/errors.py\", line 162, in __call__\n    await self.app(scope, receive, _send)\n  File \"/usr/local/lib/python3.12/site-packages/starlette/middleware/base.py\", line 108, in __call__\n    response = await self.dispatch_func(request, call_next)\n               ^^^^^^^^^^^^^^^^^^^^^^^^^^^^^^^^^^^^^^^^^^^^\n  File \"/app/src/main.py\", line 325, in validate_request\n    return await call_next(request)\n           ^^^^^^^^^^^^^^^^^^^^^^^^\n  File \"/usr/local/lib/python3.12/site-packages/starlette/middleware/base.py\", line 84, in call_next\n    raise app_exc\n  File \"/usr/local/lib/python3.12/site-packages/starlette/middleware/base.py\", line 70, in coro\n    await self.app(scope, receive_or_disconnect, send_no_error)\n  File \"/usr/local/lib/python3.12/site-packages/starlette/middleware/base.py\", line 108, in __call__\n    response = await self.dispatch_func(request, call_next)\n               ^^^^^^^^^^^^^^^^^^^^^^^^^^^^^^^^^^^^^^^^^^^^\n  File \"/app/src/main.py\", line 198, in add_security_headers\n    response = await call_next(request)\n               ^^^^^^^^^^^^^^^^^^^^^^^^\n  File \"/usr/local/lib/python3.12/site-packages/starlette/middleware/base.py\", line 84, in call_next\n    raise app_exc\n  File \"/usr/local/lib/python3.12/site-packages/starlette/middleware/base.py\", line 70, in coro\n    await self.app(scope, receive_or_disconnect, send_no_error)\n  File \"/usr/local/lib/python3.12/site-packages/starlette/middleware/base.py\", line 108, in __call__\n    response = await self.dispatch_func(request, call_next)\n               ^^^^^^^^^^^^^^^^^^^^^^^^^^^^^^^^^^^^^^^^^^^^\n  File \"/usr/local/lib/python3.12/site-packages/slowapi/middleware.py\", line 136, in dispatch\n    response = await call_next(request)\n               ^^^^^^^^^^^^^^^^^^^^^^^^\n  File \"/usr/local/lib/python3.12/site-packages/starlette/middleware/base.py\", line 84, in call_next\n    raise app_exc\n  File \"/usr/local/lib/python3.12/site-packages/starlette/middleware/base.py\", line 70, in coro\n    await self.app(scope, receive_or_disconnect, send_no_error)\n  File \"/usr/local/lib/python3.12/site-packages/starlette/middleware/cors.py\", line 83, in __call__\n    await self.app(scope, receive, send)\n  File \"/usr/local/lib/python3.12/site-packages/starlette/middleware/exceptions.py\", line 79, in __call__\n    raise exc\n  File \"/usr/local/lib/python3.12/site-packages/starlette/middleware/exceptions.py\", line 68, in __call__\n    await self.app(scope, receive, sender)\n  File \"/usr/local/lib/python3.12/site-packages/fastapi/middleware/asyncexitstack.py\", line 20, in __call__\n    raise e\n  File \"/usr/local/lib/python3.12/site-packages/fastapi/middleware/asyncexitstack.py\", line 17, in __call__\n    await self.app(scope, receive, send)\n  File \"/usr/local/lib/python3.12/site-packages/starlette/routing.py\", line 718, in __call__\n    await route.handle(scope, receive, send)\n  File \"/usr/local/lib/python3.12/site-packages/starlette/routing.py\", line 276, in handle\n    await self.app(scope, receive, send)\n  File \"/usr/local/lib/python3.12/site-packages/starlette/routing.py\", line 66, in app\n    response = await func(request)\n               ^^^^^^^^^^^^^^^^^^^\n  File \"/usr/local/lib/python3.12/site-packages/fastapi/routing.py\", line 274, in app\n    raw_response = await run_endpoint_function(\n                   ^^^^^^^^^^^^^^^^^^^^^^^^^^^^\n  File \"/usr/local/lib/python3.12/site-packages/fastapi/routing.py\", line 191, in run_endpoint_function\n    return await dependant.call(**values)\n           ^^^^^^^^^^^^^^^^^^^^^^^^^^^^^^\n  File \"/app/src/api/user.py\", line 533, in get_account_balance\n    logger.error(f\"Account balance error: {e}\")\n    ^^^^^^\nNameError: name 'logger' is not defined", "taskName": "Task-64", "asctime": "2025-10-16 21:40:41,550"}
{"timestamp": "2025-10-16 21:41:02", "level": "ERROR", "logger": "src.bot.dydx_client", "message": "Failed to create dYdX client: The use of the Mnemonic features of Account is disabled by default until its API stabilizes. To use these features, please enable them by running `Account.enable_unaudited_hdwallet_features()` and try again.", "taskName": "starlette.middleware.base.BaseHTTPMiddleware.__call__.<locals>.call_next.<locals>.coro", "asctime": "2025-10-16 21:41:02,286"}
{"timestamp": "2025-10-16 21:41:02", "level": "ERROR", "logger": "src.main", "message": "Unhandled exception: name 'logger' is not defined", "exception": "Traceback (most recent call last):\n  File \"/usr/local/lib/python3.12/site-packages/anyio/streams/memory.py\", line 98, in receive\n    return self.receive_nowait()\n           ^^^^^^^^^^^^^^^^^^^^^\n  File \"/usr/local/lib/python3.12/site-packages/anyio/streams/memory.py\", line 93, in receive_nowait\n    raise WouldBlock\nanyio.WouldBlock\n\nDuring handling of the above exception, another exception occurred:\n\nTraceback (most recent call last):\n  File \"/usr/local/lib/python3.12/site-packages/starlette/middleware/base.py\", line 78, in call_next\n    message = await recv_stream.receive()\n              ^^^^^^^^^^^^^^^^^^^^^^^^^^^\n  File \"/usr/local/lib/python3.12/site-packages/anyio/streams/memory.py\", line 118, in receive\n    raise EndOfStream\nanyio.EndOfStream\n\nDuring handling of the above exception, another exception occurred:\n\nTraceback (most recent call last):\n  File \"/usr/local/lib/python3.12/site-packages/starlette/middleware/errors.py\", line 162, in __call__\n    await self.app(scope, receive, _send)\n  File \"/usr/local/lib/python3.12/site-packages/starlette/middleware/base.py\", line 108, in __call__\n    response = await self.dispatch_func(request, call_next)\n               ^^^^^^^^^^^^^^^^^^^^^^^^^^^^^^^^^^^^^^^^^^^^\n  File \"/app/src/main.py\", line 325, in validate_request\n    return await call_next(request)\n           ^^^^^^^^^^^^^^^^^^^^^^^^\n  File \"/usr/local/lib/python3.12/site-packages/starlette/middleware/base.py\", line 84, in call_next\n    raise app_exc\n  File \"/usr/local/lib/python3.12/site-packages/starlette/middleware/base.py\", line 70, in coro\n    await self.app(scope, receive_or_disconnect, send_no_error)\n  File \"/usr/local/lib/python3.12/site-packages/starlette/middleware/base.py\", line 108, in __call__\n    response = await self.dispatch_func(request, call_next)\n               ^^^^^^^^^^^^^^^^^^^^^^^^^^^^^^^^^^^^^^^^^^^^\n  File \"/app/src/main.py\", line 198, in add_security_headers\n    response = await call_next(request)\n               ^^^^^^^^^^^^^^^^^^^^^^^^\n  File \"/usr/local/lib/python3.12/site-packages/starlette/middleware/base.py\", line 84, in call_next\n    raise app_exc\n  File \"/usr/local/lib/python3.12/site-packages/starlette/middleware/base.py\", line 70, in coro\n    await self.app(scope, receive_or_disconnect, send_no_error)\n  File \"/usr/local/lib/python3.12/site-packages/starlette/middleware/base.py\", line 108, in __call__\n    response = await self.dispatch_func(request, call_next)\n               ^^^^^^^^^^^^^^^^^^^^^^^^^^^^^^^^^^^^^^^^^^^^\n  File \"/usr/local/lib/python3.12/site-packages/slowapi/middleware.py\", line 136, in dispatch\n    response = await call_next(request)\n               ^^^^^^^^^^^^^^^^^^^^^^^^\n  File \"/usr/local/lib/python3.12/site-packages/starlette/middleware/base.py\", line 84, in call_next\n    raise app_exc\n  File \"/usr/local/lib/python3.12/site-packages/starlette/middleware/base.py\", line 70, in coro\n    await self.app(scope, receive_or_disconnect, send_no_error)\n  File \"/usr/local/lib/python3.12/site-packages/starlette/middleware/cors.py\", line 83, in __call__\n    await self.app(scope, receive, send)\n  File \"/usr/local/lib/python3.12/site-packages/starlette/middleware/exceptions.py\", line 79, in __call__\n    raise exc\n  File \"/usr/local/lib/python3.12/site-packages/starlette/middleware/exceptions.py\", line 68, in __call__\n    await self.app(scope, receive, sender)\n  File \"/usr/local/lib/python3.12/site-packages/fastapi/middleware/asyncexitstack.py\", line 20, in __call__\n    raise e\n  File \"/usr/local/lib/python3.12/site-packages/fastapi/middleware/asyncexitstack.py\", line 17, in __call__\n    await self.app(scope, receive, send)\n  File \"/usr/local/lib/python3.12/site-packages/starlette/routing.py\", line 718, in __call__\n    await route.handle(scope, receive, send)\n  File \"/usr/local/lib/python3.12/site-packages/starlette/routing.py\", line 276, in handle\n    await self.app(scope, receive, send)\n  File \"/usr/local/lib/python3.12/site-packages/starlette/routing.py\", line 66, in app\n    response = await func(request)\n               ^^^^^^^^^^^^^^^^^^^\n  File \"/usr/local/lib/python3.12/site-packages/fastapi/routing.py\", line 274, in app\n    raw_response = await run_endpoint_function(\n                   ^^^^^^^^^^^^^^^^^^^^^^^^^^^^\n  File \"/usr/local/lib/python3.12/site-packages/fastapi/routing.py\", line 191, in run_endpoint_function\n    return await dependant.call(**values)\n           ^^^^^^^^^^^^^^^^^^^^^^^^^^^^^^\n  File \"/app/src/api/user.py\", line 533, in get_account_balance\n    logger.error(f\"Account balance error: {e}\")\n    ^^^^^^\nNameError: name 'logger' is not defined", "taskName": "Task-101", "asctime": "2025-10-16 21:41:02,287"}
{"timestamp": "2025-10-16 21:41:45", "level": "ERROR", "logger": "src.main", "message": "Failed to initialize position monitoring worker: '_GeneratorContextManager' object is not an iterator", "taskName": "Task-2", "asctime": "2025-10-16 21:41:45,399"}
{"timestamp": "2025-10-16 21:42:03", "level": "ERROR", "logger": "src.bot.dydx_client", "message": "Failed to create dYdX client: The use of the Mnemonic features of Account is disabled by default until its API stabilizes. To use these features, please enable them by running `Account.enable_unaudited_hdwallet_features()` and try again.", "taskName": "starlette.middleware.base.BaseHTTPMiddleware.__call__.<locals>.call_next.<locals>.coro", "asctime": "2025-10-16 21:42:03,271"}
{"timestamp": "2025-10-16 21:42:03", "level": "ERROR", "logger": "src.api.user", "message": "Failed to create dYdX client: Client creation failed: The use of the Mnemonic features of Account is disabled by default until its API stabilizes. To use these features, please enable them by running `Account.enable_unaudited_hdwallet_features()` and try again.", "taskName": "starlette.middleware.base.BaseHTTPMiddleware.__call__.<locals>.call_next.<locals>.coro", "asctime": "2025-10-16 21:42:03,272"}
{"timestamp": "2025-10-16 21:42:22", "level": "ERROR", "logger": "src.bot.dydx_client", "message": "Failed to create dYdX client: The use of the Mnemonic features of Account is disabled by default until its API stabilizes. To use these features, please enable them by running `Account.enable_unaudited_hdwallet_features()` and try again.", "taskName": "starlette.middleware.base.BaseHTTPMiddleware.__call__.<locals>.call_next.<locals>.coro", "asctime": "2025-10-16 21:42:22,312"}
{"timestamp": "2025-10-16 21:42:22", "level": "ERROR", "logger": "src.api.user", "message": "Failed to create dYdX client: Client creation failed: The use of the Mnemonic features of Account is disabled by default until its API stabilizes. To use these features, please enable them by running `Account.enable_unaudited_hdwallet_features()` and try again.", "taskName": "starlette.middleware.base.BaseHTTPMiddleware.__call__.<locals>.call_next.<locals>.coro", "asctime": "2025-10-16 21:42:22,313"}
{"timestamp": "2025-10-16 21:42:23", "level": "ERROR", "logger": "src.bot.dydx_client", "message": "Failed to create dYdX client: The use of the Mnemonic features of Account is disabled by default until its API stabilizes. To use these features, please enable them by running `Account.enable_unaudited_hdwallet_features()` and try again.", "taskName": "starlette.middleware.base.BaseHTTPMiddleware.__call__.<locals>.call_next.<locals>.coro", "asctime": "2025-10-16 21:42:23,825"}
{"timestamp": "2025-10-16 21:42:23", "level": "ERROR", "logger": "src.api.user", "message": "Failed to create dYdX client: Client creation failed: The use of the Mnemonic features of Account is disabled by default until its API stabilizes. To use these features, please enable them by running `Account.enable_unaudited_hdwallet_features()` and try again.", "taskName": "starlette.middleware.base.BaseHTTPMiddleware.__call__.<locals>.call_next.<locals>.coro", "asctime": "2025-10-16 21:42:23,826"}
{"timestamp": "2025-10-16 21:42:24", "level": "ERROR", "logger": "src.bot.dydx_client", "message": "Failed to create dYdX client: The use of the Mnemonic features of Account is disabled by default until its API stabilizes. To use these features, please enable them by running `Account.enable_unaudited_hdwallet_features()` and try again.", "taskName": "starlette.middleware.base.BaseHTTPMiddleware.__call__.<locals>.call_next.<locals>.coro", "asctime": "2025-10-16 21:42:24,046"}
{"timestamp": "2025-10-16 21:42:24", "level": "ERROR", "logger": "src.api.user", "message": "Failed to create dYdX client: Client creation failed: The use of the Mnemonic features of Account is disabled by default until its API stabilizes. To use these features, please enable them by running `Account.enable_unaudited_hdwallet_features()` and try again.", "taskName": "starlette.middleware.base.BaseHTTPMiddleware.__call__.<locals>.call_next.<locals>.coro", "asctime": "2025-10-16 21:42:24,047"}
{"timestamp": "2025-10-16 21:42:24", "level": "ERROR", "logger": "src.bot.dydx_client", "message": "Failed to create dYdX client: The use of the Mnemonic features of Account is disabled by default until its API stabilizes. To use these features, please enable them by running `Account.enable_unaudited_hdwallet_features()` and try again.", "taskName": "starlette.middleware.base.BaseHTTPMiddleware.__call__.<locals>.call_next.<locals>.coro", "asctime": "2025-10-16 21:42:24,231"}
{"timestamp": "2025-10-16 21:42:24", "level": "ERROR", "logger": "src.api.user", "message": "Failed to create dYdX client: Client creation failed: The use of the Mnemonic features of Account is disabled by default until its API stabilizes. To use these features, please enable them by running `Account.enable_unaudited_hdwallet_features()` and try again.", "taskName": "starlette.middleware.base.BaseHTTPMiddleware.__call__.<locals>.call_next.<locals>.coro", "asctime": "2025-10-16 21:42:24,232"}
{"timestamp": "2025-10-16 21:43:37", "level": "ERROR", "logger": "src.main", "message": "Failed to initialize position monitoring worker: '_GeneratorContextManager' object is not an iterator", "taskName": "Task-2", "asctime": "2025-10-16 21:43:37,705"}
{"timestamp": "2025-10-16 21:43:50", "level": "ERROR", "logger": "src.bot.dydx_client", "message": "Failed to create dYdX client: NodeConfig.__init__() missing 1 required positional argument: 'channel'", "taskName": "starlette.middleware.base.BaseHTTPMiddleware.__call__.<locals>.call_next.<locals>.coro", "asctime": "2025-10-16 21:43:50,414"}
{"timestamp": "2025-10-16 21:43:50", "level": "ERROR", "logger": "src.api.user", "message": "Failed to create dYdX client: Client creation failed: NodeConfig.__init__() missing 1 required positional argument: 'channel'", "taskName": "starlette.middleware.base.BaseHTTPMiddleware.__call__.<locals>.call_next.<locals>.coro", "asctime": "2025-10-16 21:43:50,414"}
{"timestamp": "2025-10-16 21:45:27", "level": "ERROR", "logger": "src.main", "message": "Failed to initialize position monitoring worker: '_GeneratorContextManager' object is not an iterator", "taskName": "Task-2", "asctime": "2025-10-16 21:45:27,901"}
{"timestamp": "2025-10-16 21:59:29", "level": "ERROR", "logger": "src.main", "message": "Failed to initialize position monitoring worker: '_GeneratorContextManager' object is not an iterator", "taskName": "Task-2", "asctime": "2025-10-16 21:59:29,098"}
{"timestamp": "2025-10-17 06:51:27", "level": "ERROR", "logger": "src.api.webhooks", "message": "Failed to log webhook event: '_GeneratorContextManager' object has no attribute 'add'", "taskName": "starlette.middleware.base.BaseHTTPMiddleware.__call__.<locals>.call_next.<locals>.coro", "asctime": "2025-10-17 06:51:27,849"}
{"timestamp": "2025-10-17 06:51:27", "level": "ERROR", "logger": "src.api.webhooks", "message": "Failed to log webhook event: '_GeneratorContextManager' object has no attribute 'add'", "taskName": "starlette.middleware.base.BaseHTTPMiddleware.__call__.<locals>.call_next.<locals>.coro", "asctime": "2025-10-17 06:51:27,866"}
{"timestamp": "2025-10-17 06:53:34", "level": "ERROR", "logger": "src.api.webhooks", "message": "Failed to log webhook event: '_GeneratorContextManager' object has no attribute 'add'", "taskName": "starlette.middleware.base.BaseHTTPMiddleware.__call__.<locals>.call_next.<locals>.coro", "asctime": "2025-10-17 06:53:34,292"}
{"timestamp": "2025-10-17 06:53:34", "level": "ERROR", "logger": "src.api.webhooks", "message": "Failed to log webhook event: '_GeneratorContextManager' object has no attribute 'add'", "taskName": "starlette.middleware.base.BaseHTTPMiddleware.__call__.<locals>.call_next.<locals>.coro", "asctime": "2025-10-17 06:53:34,297"}
{"timestamp": "2025-10-17 06:54:47", "level": "ERROR", "logger": "src.main", "message": "Failed to initialize position monitoring worker: '_GeneratorContextManager' object is not an iterator", "taskName": "Task-2", "asctime": "2025-10-17 06:54:47,916"}
{"timestamp": "2025-10-17 06:55:19", "level": "ERROR", "logger": "src.main", "message": "Unhandled exception: '_GeneratorContextManager' object does not support the asynchronous context manager protocol", "exception": "Traceback (most recent call last):\n  File \"/usr/local/lib/python3.12/site-packages/anyio/streams/memory.py\", line 98, in receive\n    return self.receive_nowait()\n           ^^^^^^^^^^^^^^^^^^^^^\n  File \"/usr/local/lib/python3.12/site-packages/anyio/streams/memory.py\", line 93, in receive_nowait\n    raise WouldBlock\nanyio.WouldBlock\n\nDuring handling of the above exception, another exception occurred:\n\nTraceback (most recent call last):\n  File \"/usr/local/lib/python3.12/site-packages/starlette/middleware/base.py\", line 78, in call_next\n    message = await recv_stream.receive()\n              ^^^^^^^^^^^^^^^^^^^^^^^^^^^\n  File \"/usr/local/lib/python3.12/site-packages/anyio/streams/memory.py\", line 118, in receive\n    raise EndOfStream\nanyio.EndOfStream\n\nDuring handling of the above exception, another exception occurred:\n\nTraceback (most recent call last):\n  File \"/usr/local/lib/python3.12/site-packages/starlette/middleware/errors.py\", line 162, in __call__\n    await self.app(scope, receive, _send)\n  File \"/usr/local/lib/python3.12/site-packages/starlette/middleware/base.py\", line 108, in __call__\n    response = await self.dispatch_func(request, call_next)\n               ^^^^^^^^^^^^^^^^^^^^^^^^^^^^^^^^^^^^^^^^^^^^\n  File \"/app/src/main.py\", line 325, in validate_request\n    return await call_next(request)\n           ^^^^^^^^^^^^^^^^^^^^^^^^\n  File \"/usr/local/lib/python3.12/site-packages/starlette/middleware/base.py\", line 84, in call_next\n    raise app_exc\n  File \"/usr/local/lib/python3.12/site-packages/starlette/middleware/base.py\", line 70, in coro\n    await self.app(scope, receive_or_disconnect, send_no_error)\n  File \"/usr/local/lib/python3.12/site-packages/starlette/middleware/base.py\", line 108, in __call__\n    response = await self.dispatch_func(request, call_next)\n               ^^^^^^^^^^^^^^^^^^^^^^^^^^^^^^^^^^^^^^^^^^^^\n  File \"/app/src/main.py\", line 198, in add_security_headers\n    response = await call_next(request)\n               ^^^^^^^^^^^^^^^^^^^^^^^^\n  File \"/usr/local/lib/python3.12/site-packages/starlette/middleware/base.py\", line 84, in call_next\n    raise app_exc\n  File \"/usr/local/lib/python3.12/site-packages/starlette/middleware/base.py\", line 70, in coro\n    await self.app(scope, receive_or_disconnect, send_no_error)\n  File \"/usr/local/lib/python3.12/site-packages/starlette/middleware/base.py\", line 108, in __call__\n    response = await self.dispatch_func(request, call_next)\n               ^^^^^^^^^^^^^^^^^^^^^^^^^^^^^^^^^^^^^^^^^^^^\n  File \"/usr/local/lib/python3.12/site-packages/slowapi/middleware.py\", line 136, in dispatch\n    response = await call_next(request)\n               ^^^^^^^^^^^^^^^^^^^^^^^^\n  File \"/usr/local/lib/python3.12/site-packages/starlette/middleware/base.py\", line 84, in call_next\n    raise app_exc\n  File \"/usr/local/lib/python3.12/site-packages/starlette/middleware/base.py\", line 70, in coro\n    await self.app(scope, receive_or_disconnect, send_no_error)\n  File \"/usr/local/lib/python3.12/site-packages/starlette/middleware/cors.py\", line 83, in __call__\n    await self.app(scope, receive, send)\n  File \"/usr/local/lib/python3.12/site-packages/starlette/middleware/exceptions.py\", line 79, in __call__\n    raise exc\n  File \"/usr/local/lib/python3.12/site-packages/starlette/middleware/exceptions.py\", line 68, in __call__\n    await self.app(scope, receive, sender)\n  File \"/usr/local/lib/python3.12/site-packages/fastapi/middleware/asyncexitstack.py\", line 20, in __call__\n    raise e\n  File \"/usr/local/lib/python3.12/site-packages/fastapi/middleware/asyncexitstack.py\", line 17, in __call__\n    await self.app(scope, receive, send)\n  File \"/usr/local/lib/python3.12/site-packages/starlette/routing.py\", line 718, in __call__\n    await route.handle(scope, receive, send)\n  File \"/usr/local/lib/python3.12/site-packages/starlette/routing.py\", line 276, in handle\n    await self.app(scope, receive, send)\n  File \"/usr/local/lib/python3.12/site-packages/starlette/routing.py\", line 66, in app\n    response = await func(request)\n               ^^^^^^^^^^^^^^^^^^^\n  File \"/usr/local/lib/python3.12/site-packages/fastapi/routing.py\", line 264, in app\n    solved_result = await solve_dependencies(\n                    ^^^^^^^^^^^^^^^^^^^^^^^^^\n  File \"/usr/local/lib/python3.12/site-packages/fastapi/dependencies/utils.py\", line 563, in solve_dependencies\n    solved_result = await solve_dependencies(\n                    ^^^^^^^^^^^^^^^^^^^^^^^^^\n  File \"/usr/local/lib/python3.12/site-packages/fastapi/dependencies/utils.py\", line 588, in solve_dependencies\n    solved = await solve_generator(\n             ^^^^^^^^^^^^^^^^^^^^^^\n  File \"/usr/local/lib/python3.12/site-packages/fastapi/dependencies/utils.py\", line 513, in solve_generator\n    return await stack.enter_async_context(cm)\n           ^^^^^^^^^^^^^^^^^^^^^^^^^^^^^^^^^^^\n  File \"/usr/local/lib/python3.12/contextlib.py\", line 659, in enter_async_context\n    result = await _enter(cm)\n             ^^^^^^^^^^^^^^^^\n  File \"/usr/local/lib/python3.12/contextlib.py\", line 210, in __aenter__\n    return await anext(self.gen)\n           ^^^^^^^^^^^^^^^^^^^^^\n  File \"/app/src/api/webhooks.py\", line 2242, in get_db_session\n    async with db_manager.get_session() as session:\n               ^^^^^^^^^^^^^^^^^^^^^^^^\nTypeError: '_GeneratorContextManager' object does not support the asynchronous context manager protocol", "taskName": "Task-34", "asctime": "2025-10-17 06:55:19,909"}
{"timestamp": "2025-10-17 06:55:34", "level": "ERROR", "logger": "src.main", "message": "Unhandled exception: '_GeneratorContextManager' object does not support the asynchronous context manager protocol", "exception": "Traceback (most recent call last):\n  File \"/usr/local/lib/python3.12/site-packages/anyio/streams/memory.py\", line 98, in receive\n    return self.receive_nowait()\n           ^^^^^^^^^^^^^^^^^^^^^\n  File \"/usr/local/lib/python3.12/site-packages/anyio/streams/memory.py\", line 93, in receive_nowait\n    raise WouldBlock\nanyio.WouldBlock\n\nDuring handling of the above exception, another exception occurred:\n\nTraceback (most recent call last):\n  File \"/usr/local/lib/python3.12/site-packages/starlette/middleware/base.py\", line 78, in call_next\n    message = await recv_stream.receive()\n              ^^^^^^^^^^^^^^^^^^^^^^^^^^^\n  File \"/usr/local/lib/python3.12/site-packages/anyio/streams/memory.py\", line 118, in receive\n    raise EndOfStream\nanyio.EndOfStream\n\nDuring handling of the above exception, another exception occurred:\n\nTraceback (most recent call last):\n  File \"/usr/local/lib/python3.12/site-packages/starlette/middleware/errors.py\", line 162, in __call__\n    await self.app(scope, receive, _send)\n  File \"/usr/local/lib/python3.12/site-packages/starlette/middleware/base.py\", line 108, in __call__\n    response = await self.dispatch_func(request, call_next)\n               ^^^^^^^^^^^^^^^^^^^^^^^^^^^^^^^^^^^^^^^^^^^^\n  File \"/app/src/main.py\", line 325, in validate_request\n    return await call_next(request)\n           ^^^^^^^^^^^^^^^^^^^^^^^^\n  File \"/usr/local/lib/python3.12/site-packages/starlette/middleware/base.py\", line 84, in call_next\n    raise app_exc\n  File \"/usr/local/lib/python3.12/site-packages/starlette/middleware/base.py\", line 70, in coro\n    await self.app(scope, receive_or_disconnect, send_no_error)\n  File \"/usr/local/lib/python3.12/site-packages/starlette/middleware/base.py\", line 108, in __call__\n    response = await self.dispatch_func(request, call_next)\n               ^^^^^^^^^^^^^^^^^^^^^^^^^^^^^^^^^^^^^^^^^^^^\n  File \"/app/src/main.py\", line 198, in add_security_headers\n    response = await call_next(request)\n               ^^^^^^^^^^^^^^^^^^^^^^^^\n  File \"/usr/local/lib/python3.12/site-packages/starlette/middleware/base.py\", line 84, in call_next\n    raise app_exc\n  File \"/usr/local/lib/python3.12/site-packages/starlette/middleware/base.py\", line 70, in coro\n    await self.app(scope, receive_or_disconnect, send_no_error)\n  File \"/usr/local/lib/python3.12/site-packages/starlette/middleware/base.py\", line 108, in __call__\n    response = await self.dispatch_func(request, call_next)\n               ^^^^^^^^^^^^^^^^^^^^^^^^^^^^^^^^^^^^^^^^^^^^\n  File \"/usr/local/lib/python3.12/site-packages/slowapi/middleware.py\", line 136, in dispatch\n    response = await call_next(request)\n               ^^^^^^^^^^^^^^^^^^^^^^^^\n  File \"/usr/local/lib/python3.12/site-packages/starlette/middleware/base.py\", line 84, in call_next\n    raise app_exc\n  File \"/usr/local/lib/python3.12/site-packages/starlette/middleware/base.py\", line 70, in coro\n    await self.app(scope, receive_or_disconnect, send_no_error)\n  File \"/usr/local/lib/python3.12/site-packages/starlette/middleware/cors.py\", line 83, in __call__\n    await self.app(scope, receive, send)\n  File \"/usr/local/lib/python3.12/site-packages/starlette/middleware/exceptions.py\", line 79, in __call__\n    raise exc\n  File \"/usr/local/lib/python3.12/site-packages/starlette/middleware/exceptions.py\", line 68, in __call__\n    await self.app(scope, receive, sender)\n  File \"/usr/local/lib/python3.12/site-packages/fastapi/middleware/asyncexitstack.py\", line 20, in __call__\n    raise e\n  File \"/usr/local/lib/python3.12/site-packages/fastapi/middleware/asyncexitstack.py\", line 17, in __call__\n    await self.app(scope, receive, send)\n  File \"/usr/local/lib/python3.12/site-packages/starlette/routing.py\", line 718, in __call__\n    await route.handle(scope, receive, send)\n  File \"/usr/local/lib/python3.12/site-packages/starlette/routing.py\", line 276, in handle\n    await self.app(scope, receive, send)\n  File \"/usr/local/lib/python3.12/site-packages/starlette/routing.py\", line 66, in app\n    response = await func(request)\n               ^^^^^^^^^^^^^^^^^^^\n  File \"/usr/local/lib/python3.12/site-packages/fastapi/routing.py\", line 264, in app\n    solved_result = await solve_dependencies(\n                    ^^^^^^^^^^^^^^^^^^^^^^^^^\n  File \"/usr/local/lib/python3.12/site-packages/fastapi/dependencies/utils.py\", line 563, in solve_dependencies\n    solved_result = await solve_dependencies(\n                    ^^^^^^^^^^^^^^^^^^^^^^^^^\n  File \"/usr/local/lib/python3.12/site-packages/fastapi/dependencies/utils.py\", line 588, in solve_dependencies\n    solved = await solve_generator(\n             ^^^^^^^^^^^^^^^^^^^^^^\n  File \"/usr/local/lib/python3.12/site-packages/fastapi/dependencies/utils.py\", line 513, in solve_generator\n    return await stack.enter_async_context(cm)\n           ^^^^^^^^^^^^^^^^^^^^^^^^^^^^^^^^^^^\n  File \"/usr/local/lib/python3.12/contextlib.py\", line 659, in enter_async_context\n    result = await _enter(cm)\n             ^^^^^^^^^^^^^^^^\n  File \"/usr/local/lib/python3.12/contextlib.py\", line 210, in __aenter__\n    return await anext(self.gen)\n           ^^^^^^^^^^^^^^^^^^^^^\n  File \"/app/src/api/webhooks.py\", line 2242, in get_db_session\n    async with db_manager.get_session() as session:\n               ^^^^^^^^^^^^^^^^^^^^^^^^\nTypeError: '_GeneratorContextManager' object does not support the asynchronous context manager protocol", "taskName": "Task-41", "asctime": "2025-10-17 06:55:34,318"}
{"timestamp": "2025-10-17 06:56:38", "level": "ERROR", "logger": "src.main", "message": "Unhandled exception: ", "exception": "Traceback (most recent call last):\n  File \"/usr/local/lib/python3.12/site-packages/starlette/middleware/errors.py\", line 162, in __call__\n    await self.app(scope, receive, _send)\n  File \"/usr/local/lib/python3.12/site-packages/starlette/middleware/base.py\", line 108, in __call__\n    response = await self.dispatch_func(request, call_next)\n               ^^^^^^^^^^^^^^^^^^^^^^^^^^^^^^^^^^^^^^^^^^^^\n  File \"/app/src/main.py\", line 246, in validate_request\n    raise HTTPException(\nfastapi.exceptions.HTTPException", "taskName": "Task-78", "asctime": "2025-10-17 06:56:38,303"}
{"timestamp": "2025-10-17 06:56:54", "level": "ERROR", "logger": "src.main", "message": "Unhandled exception: '_GeneratorContextManager' object does not support the asynchronous context manager protocol", "exception": "Traceback (most recent call last):\n  File \"/usr/local/lib/python3.12/site-packages/anyio/streams/memory.py\", line 98, in receive\n    return self.receive_nowait()\n           ^^^^^^^^^^^^^^^^^^^^^\n  File \"/usr/local/lib/python3.12/site-packages/anyio/streams/memory.py\", line 93, in receive_nowait\n    raise WouldBlock\nanyio.WouldBlock\n\nDuring handling of the above exception, another exception occurred:\n\nTraceback (most recent call last):\n  File \"/usr/local/lib/python3.12/site-packages/starlette/middleware/base.py\", line 78, in call_next\n    message = await recv_stream.receive()\n              ^^^^^^^^^^^^^^^^^^^^^^^^^^^\n  File \"/usr/local/lib/python3.12/site-packages/anyio/streams/memory.py\", line 118, in receive\n    raise EndOfStream\nanyio.EndOfStream\n\nDuring handling of the above exception, another exception occurred:\n\nTraceback (most recent call last):\n  File \"/usr/local/lib/python3.12/site-packages/starlette/middleware/errors.py\", line 162, in __call__\n    await self.app(scope, receive, _send)\n  File \"/usr/local/lib/python3.12/site-packages/starlette/middleware/base.py\", line 108, in __call__\n    response = await self.dispatch_func(request, call_next)\n               ^^^^^^^^^^^^^^^^^^^^^^^^^^^^^^^^^^^^^^^^^^^^\n  File \"/app/src/main.py\", line 325, in validate_request\n    return await call_next(request)\n           ^^^^^^^^^^^^^^^^^^^^^^^^\n  File \"/usr/local/lib/python3.12/site-packages/starlette/middleware/base.py\", line 84, in call_next\n    raise app_exc\n  File \"/usr/local/lib/python3.12/site-packages/starlette/middleware/base.py\", line 70, in coro\n    await self.app(scope, receive_or_disconnect, send_no_error)\n  File \"/usr/local/lib/python3.12/site-packages/starlette/middleware/base.py\", line 108, in __call__\n    response = await self.dispatch_func(request, call_next)\n               ^^^^^^^^^^^^^^^^^^^^^^^^^^^^^^^^^^^^^^^^^^^^\n  File \"/app/src/main.py\", line 198, in add_security_headers\n    response = await call_next(request)\n               ^^^^^^^^^^^^^^^^^^^^^^^^\n  File \"/usr/local/lib/python3.12/site-packages/starlette/middleware/base.py\", line 84, in call_next\n    raise app_exc\n  File \"/usr/local/lib/python3.12/site-packages/starlette/middleware/base.py\", line 70, in coro\n    await self.app(scope, receive_or_disconnect, send_no_error)\n  File \"/usr/local/lib/python3.12/site-packages/starlette/middleware/base.py\", line 108, in __call__\n    response = await self.dispatch_func(request, call_next)\n               ^^^^^^^^^^^^^^^^^^^^^^^^^^^^^^^^^^^^^^^^^^^^\n  File \"/usr/local/lib/python3.12/site-packages/slowapi/middleware.py\", line 136, in dispatch\n    response = await call_next(request)\n               ^^^^^^^^^^^^^^^^^^^^^^^^\n  File \"/usr/local/lib/python3.12/site-packages/starlette/middleware/base.py\", line 84, in call_next\n    raise app_exc\n  File \"/usr/local/lib/python3.12/site-packages/starlette/middleware/base.py\", line 70, in coro\n    await self.app(scope, receive_or_disconnect, send_no_error)\n  File \"/usr/local/lib/python3.12/site-packages/starlette/middleware/cors.py\", line 83, in __call__\n    await self.app(scope, receive, send)\n  File \"/usr/local/lib/python3.12/site-packages/starlette/middleware/exceptions.py\", line 79, in __call__\n    raise exc\n  File \"/usr/local/lib/python3.12/site-packages/starlette/middleware/exceptions.py\", line 68, in __call__\n    await self.app(scope, receive, sender)\n  File \"/usr/local/lib/python3.12/site-packages/fastapi/middleware/asyncexitstack.py\", line 20, in __call__\n    raise e\n  File \"/usr/local/lib/python3.12/site-packages/fastapi/middleware/asyncexitstack.py\", line 17, in __call__\n    await self.app(scope, receive, send)\n  File \"/usr/local/lib/python3.12/site-packages/starlette/routing.py\", line 718, in __call__\n    await route.handle(scope, receive, send)\n  File \"/usr/local/lib/python3.12/site-packages/starlette/routing.py\", line 276, in handle\n    await self.app(scope, receive, send)\n  File \"/usr/local/lib/python3.12/site-packages/starlette/routing.py\", line 66, in app\n    response = await func(request)\n               ^^^^^^^^^^^^^^^^^^^\n  File \"/usr/local/lib/python3.12/site-packages/fastapi/routing.py\", line 264, in app\n    solved_result = await solve_dependencies(\n                    ^^^^^^^^^^^^^^^^^^^^^^^^^\n  File \"/usr/local/lib/python3.12/site-packages/fastapi/dependencies/utils.py\", line 563, in solve_dependencies\n    solved_result = await solve_dependencies(\n                    ^^^^^^^^^^^^^^^^^^^^^^^^^\n  File \"/usr/local/lib/python3.12/site-packages/fastapi/dependencies/utils.py\", line 588, in solve_dependencies\n    solved = await solve_generator(\n             ^^^^^^^^^^^^^^^^^^^^^^\n  File \"/usr/local/lib/python3.12/site-packages/fastapi/dependencies/utils.py\", line 513, in solve_generator\n    return await stack.enter_async_context(cm)\n           ^^^^^^^^^^^^^^^^^^^^^^^^^^^^^^^^^^^\n  File \"/usr/local/lib/python3.12/contextlib.py\", line 659, in enter_async_context\n    result = await _enter(cm)\n             ^^^^^^^^^^^^^^^^\n  File \"/usr/local/lib/python3.12/contextlib.py\", line 210, in __aenter__\n    return await anext(self.gen)\n           ^^^^^^^^^^^^^^^^^^^^^\n  File \"/app/src/api/webhooks.py\", line 2242, in get_db_session\n    async with db_manager.get_session() as session:\n               ^^^^^^^^^^^^^^^^^^^^^^^^\nTypeError: '_GeneratorContextManager' object does not support the asynchronous context manager protocol", "taskName": "Task-94", "asctime": "2025-10-17 06:56:54,994"}
{"timestamp": "2025-10-17 06:57:48", "level": "ERROR", "logger": "src.main", "message": "Unhandled exception: '_GeneratorContextManager' object does not support the asynchronous context manager protocol", "exception": "Traceback (most recent call last):\n  File \"/usr/local/lib/python3.12/site-packages/anyio/streams/memory.py\", line 98, in receive\n    return self.receive_nowait()\n           ^^^^^^^^^^^^^^^^^^^^^\n  File \"/usr/local/lib/python3.12/site-packages/anyio/streams/memory.py\", line 93, in receive_nowait\n    raise WouldBlock\nanyio.WouldBlock\n\nDuring handling of the above exception, another exception occurred:\n\nTraceback (most recent call last):\n  File \"/usr/local/lib/python3.12/site-packages/starlette/middleware/base.py\", line 78, in call_next\n    message = await recv_stream.receive()\n              ^^^^^^^^^^^^^^^^^^^^^^^^^^^\n  File \"/usr/local/lib/python3.12/site-packages/anyio/streams/memory.py\", line 118, in receive\n    raise EndOfStream\nanyio.EndOfStream\n\nDuring handling of the above exception, another exception occurred:\n\nTraceback (most recent call last):\n  File \"/usr/local/lib/python3.12/site-packages/starlette/middleware/errors.py\", line 162, in __call__\n    await self.app(scope, receive, _send)\n  File \"/usr/local/lib/python3.12/site-packages/starlette/middleware/base.py\", line 108, in __call__\n    response = await self.dispatch_func(request, call_next)\n               ^^^^^^^^^^^^^^^^^^^^^^^^^^^^^^^^^^^^^^^^^^^^\n  File \"/app/src/main.py\", line 325, in validate_request\n    return await call_next(request)\n           ^^^^^^^^^^^^^^^^^^^^^^^^\n  File \"/usr/local/lib/python3.12/site-packages/starlette/middleware/base.py\", line 84, in call_next\n    raise app_exc\n  File \"/usr/local/lib/python3.12/site-packages/starlette/middleware/base.py\", line 70, in coro\n    await self.app(scope, receive_or_disconnect, send_no_error)\n  File \"/usr/local/lib/python3.12/site-packages/starlette/middleware/base.py\", line 108, in __call__\n    response = await self.dispatch_func(request, call_next)\n               ^^^^^^^^^^^^^^^^^^^^^^^^^^^^^^^^^^^^^^^^^^^^\n  File \"/app/src/main.py\", line 198, in add_security_headers\n    response = await call_next(request)\n               ^^^^^^^^^^^^^^^^^^^^^^^^\n  File \"/usr/local/lib/python3.12/site-packages/starlette/middleware/base.py\", line 84, in call_next\n    raise app_exc\n  File \"/usr/local/lib/python3.12/site-packages/starlette/middleware/base.py\", line 70, in coro\n    await self.app(scope, receive_or_disconnect, send_no_error)\n  File \"/usr/local/lib/python3.12/site-packages/starlette/middleware/base.py\", line 108, in __call__\n    response = await self.dispatch_func(request, call_next)\n               ^^^^^^^^^^^^^^^^^^^^^^^^^^^^^^^^^^^^^^^^^^^^\n  File \"/usr/local/lib/python3.12/site-packages/slowapi/middleware.py\", line 136, in dispatch\n    response = await call_next(request)\n               ^^^^^^^^^^^^^^^^^^^^^^^^\n  File \"/usr/local/lib/python3.12/site-packages/starlette/middleware/base.py\", line 84, in call_next\n    raise app_exc\n  File \"/usr/local/lib/python3.12/site-packages/starlette/middleware/base.py\", line 70, in coro\n    await self.app(scope, receive_or_disconnect, send_no_error)\n  File \"/usr/local/lib/python3.12/site-packages/starlette/middleware/cors.py\", line 83, in __call__\n    await self.app(scope, receive, send)\n  File \"/usr/local/lib/python3.12/site-packages/starlette/middleware/exceptions.py\", line 79, in __call__\n    raise exc\n  File \"/usr/local/lib/python3.12/site-packages/starlette/middleware/exceptions.py\", line 68, in __call__\n    await self.app(scope, receive, sender)\n  File \"/usr/local/lib/python3.12/site-packages/fastapi/middleware/asyncexitstack.py\", line 20, in __call__\n    raise e\n  File \"/usr/local/lib/python3.12/site-packages/fastapi/middleware/asyncexitstack.py\", line 17, in __call__\n    await self.app(scope, receive, send)\n  File \"/usr/local/lib/python3.12/site-packages/starlette/routing.py\", line 718, in __call__\n    await route.handle(scope, receive, send)\n  File \"/usr/local/lib/python3.12/site-packages/starlette/routing.py\", line 276, in handle\n    await self.app(scope, receive, send)\n  File \"/usr/local/lib/python3.12/site-packages/starlette/routing.py\", line 66, in app\n    response = await func(request)\n               ^^^^^^^^^^^^^^^^^^^\n  File \"/usr/local/lib/python3.12/site-packages/fastapi/routing.py\", line 264, in app\n    solved_result = await solve_dependencies(\n                    ^^^^^^^^^^^^^^^^^^^^^^^^^\n  File \"/usr/local/lib/python3.12/site-packages/fastapi/dependencies/utils.py\", line 563, in solve_dependencies\n    solved_result = await solve_dependencies(\n                    ^^^^^^^^^^^^^^^^^^^^^^^^^\n  File \"/usr/local/lib/python3.12/site-packages/fastapi/dependencies/utils.py\", line 588, in solve_dependencies\n    solved = await solve_generator(\n             ^^^^^^^^^^^^^^^^^^^^^^\n  File \"/usr/local/lib/python3.12/site-packages/fastapi/dependencies/utils.py\", line 513, in solve_generator\n    return await stack.enter_async_context(cm)\n           ^^^^^^^^^^^^^^^^^^^^^^^^^^^^^^^^^^^\n  File \"/usr/local/lib/python3.12/contextlib.py\", line 659, in enter_async_context\n    result = await _enter(cm)\n             ^^^^^^^^^^^^^^^^\n  File \"/usr/local/lib/python3.12/contextlib.py\", line 210, in __aenter__\n    return await anext(self.gen)\n           ^^^^^^^^^^^^^^^^^^^^^\n  File \"/app/src/api/webhooks.py\", line 2242, in get_db_session\n    async with db_manager.get_session() as session:\n               ^^^^^^^^^^^^^^^^^^^^^^^^\nTypeError: '_GeneratorContextManager' object does not support the asynchronous context manager protocol", "taskName": "Task-116", "asctime": "2025-10-17 06:57:48,753"}
{"timestamp": "2025-10-17 06:58:51", "level": "ERROR", "logger": "src.main", "message": "Failed to initialize position monitoring worker: '_GeneratorContextManager' object is not an iterator", "taskName": "Task-2", "asctime": "2025-10-17 06:58:51,062"}
{"timestamp": "2025-10-17 06:59:20", "level": "ERROR", "logger": "src.main", "message": "Unhandled exception: '_GeneratorContextManager' object does not support the asynchronous context manager protocol", "exception": "Traceback (most recent call last):\n  File \"/usr/local/lib/python3.12/site-packages/anyio/streams/memory.py\", line 98, in receive\n    return self.receive_nowait()\n           ^^^^^^^^^^^^^^^^^^^^^\n  File \"/usr/local/lib/python3.12/site-packages/anyio/streams/memory.py\", line 93, in receive_nowait\n    raise WouldBlock\nanyio.WouldBlock\n\nDuring handling of the above exception, another exception occurred:\n\nTraceback (most recent call last):\n  File \"/usr/local/lib/python3.12/site-packages/starlette/middleware/base.py\", line 78, in call_next\n    message = await recv_stream.receive()\n              ^^^^^^^^^^^^^^^^^^^^^^^^^^^\n  File \"/usr/local/lib/python3.12/site-packages/anyio/streams/memory.py\", line 118, in receive\n    raise EndOfStream\nanyio.EndOfStream\n\nDuring handling of the above exception, another exception occurred:\n\nTraceback (most recent call last):\n  File \"/usr/local/lib/python3.12/site-packages/starlette/middleware/errors.py\", line 162, in __call__\n    await self.app(scope, receive, _send)\n  File \"/usr/local/lib/python3.12/site-packages/starlette/middleware/base.py\", line 108, in __call__\n    response = await self.dispatch_func(request, call_next)\n               ^^^^^^^^^^^^^^^^^^^^^^^^^^^^^^^^^^^^^^^^^^^^\n  File \"/app/src/main.py\", line 325, in validate_request\n    return await call_next(request)\n           ^^^^^^^^^^^^^^^^^^^^^^^^\n  File \"/usr/local/lib/python3.12/site-packages/starlette/middleware/base.py\", line 84, in call_next\n    raise app_exc\n  File \"/usr/local/lib/python3.12/site-packages/starlette/middleware/base.py\", line 70, in coro\n    await self.app(scope, receive_or_disconnect, send_no_error)\n  File \"/usr/local/lib/python3.12/site-packages/starlette/middleware/base.py\", line 108, in __call__\n    response = await self.dispatch_func(request, call_next)\n               ^^^^^^^^^^^^^^^^^^^^^^^^^^^^^^^^^^^^^^^^^^^^\n  File \"/app/src/main.py\", line 198, in add_security_headers\n    response = await call_next(request)\n               ^^^^^^^^^^^^^^^^^^^^^^^^\n  File \"/usr/local/lib/python3.12/site-packages/starlette/middleware/base.py\", line 84, in call_next\n    raise app_exc\n  File \"/usr/local/lib/python3.12/site-packages/starlette/middleware/base.py\", line 70, in coro\n    await self.app(scope, receive_or_disconnect, send_no_error)\n  File \"/usr/local/lib/python3.12/site-packages/starlette/middleware/base.py\", line 108, in __call__\n    response = await self.dispatch_func(request, call_next)\n               ^^^^^^^^^^^^^^^^^^^^^^^^^^^^^^^^^^^^^^^^^^^^\n  File \"/usr/local/lib/python3.12/site-packages/slowapi/middleware.py\", line 136, in dispatch\n    response = await call_next(request)\n               ^^^^^^^^^^^^^^^^^^^^^^^^\n  File \"/usr/local/lib/python3.12/site-packages/starlette/middleware/base.py\", line 84, in call_next\n    raise app_exc\n  File \"/usr/local/lib/python3.12/site-packages/starlette/middleware/base.py\", line 70, in coro\n    await self.app(scope, receive_or_disconnect, send_no_error)\n  File \"/usr/local/lib/python3.12/site-packages/starlette/middleware/cors.py\", line 83, in __call__\n    await self.app(scope, receive, send)\n  File \"/usr/local/lib/python3.12/site-packages/starlette/middleware/exceptions.py\", line 79, in __call__\n    raise exc\n  File \"/usr/local/lib/python3.12/site-packages/starlette/middleware/exceptions.py\", line 68, in __call__\n    await self.app(scope, receive, sender)\n  File \"/usr/local/lib/python3.12/site-packages/fastapi/middleware/asyncexitstack.py\", line 20, in __call__\n    raise e\n  File \"/usr/local/lib/python3.12/site-packages/fastapi/middleware/asyncexitstack.py\", line 17, in __call__\n    await self.app(scope, receive, send)\n  File \"/usr/local/lib/python3.12/site-packages/starlette/routing.py\", line 718, in __call__\n    await route.handle(scope, receive, send)\n  File \"/usr/local/lib/python3.12/site-packages/starlette/routing.py\", line 276, in handle\n    await self.app(scope, receive, send)\n  File \"/usr/local/lib/python3.12/site-packages/starlette/routing.py\", line 66, in app\n    response = await func(request)\n               ^^^^^^^^^^^^^^^^^^^\n  File \"/usr/local/lib/python3.12/site-packages/fastapi/routing.py\", line 264, in app\n    solved_result = await solve_dependencies(\n                    ^^^^^^^^^^^^^^^^^^^^^^^^^\n  File \"/usr/local/lib/python3.12/site-packages/fastapi/dependencies/utils.py\", line 563, in solve_dependencies\n    solved_result = await solve_dependencies(\n                    ^^^^^^^^^^^^^^^^^^^^^^^^^\n  File \"/usr/local/lib/python3.12/site-packages/fastapi/dependencies/utils.py\", line 588, in solve_dependencies\n    solved = await solve_generator(\n             ^^^^^^^^^^^^^^^^^^^^^^\n  File \"/usr/local/lib/python3.12/site-packages/fastapi/dependencies/utils.py\", line 513, in solve_generator\n    return await stack.enter_async_context(cm)\n           ^^^^^^^^^^^^^^^^^^^^^^^^^^^^^^^^^^^\n  File \"/usr/local/lib/python3.12/contextlib.py\", line 659, in enter_async_context\n    result = await _enter(cm)\n             ^^^^^^^^^^^^^^^^\n  File \"/usr/local/lib/python3.12/contextlib.py\", line 210, in __aenter__\n    return await anext(self.gen)\n           ^^^^^^^^^^^^^^^^^^^^^\n  File \"/app/src/db/database.py\", line 338, in get_db\n    async with db_manager.get_session() as session:\n               ^^^^^^^^^^^^^^^^^^^^^^^^\nTypeError: '_GeneratorContextManager' object does not support the asynchronous context manager protocol", "taskName": "Task-19", "asctime": "2025-10-17 06:59:20,344"}
{"timestamp": "2025-10-17 07:00:36", "level": "ERROR", "logger": "src.main", "message": "Unhandled exception: '_GeneratorContextManager' object does not support the asynchronous context manager protocol", "exception": "Traceback (most recent call last):\n  File \"/usr/local/lib/python3.12/site-packages/anyio/streams/memory.py\", line 98, in receive\n    return self.receive_nowait()\n           ^^^^^^^^^^^^^^^^^^^^^\n  File \"/usr/local/lib/python3.12/site-packages/anyio/streams/memory.py\", line 93, in receive_nowait\n    raise WouldBlock\nanyio.WouldBlock\n\nDuring handling of the above exception, another exception occurred:\n\nTraceback (most recent call last):\n  File \"/usr/local/lib/python3.12/site-packages/starlette/middleware/base.py\", line 78, in call_next\n    message = await recv_stream.receive()\n              ^^^^^^^^^^^^^^^^^^^^^^^^^^^\n  File \"/usr/local/lib/python3.12/site-packages/anyio/streams/memory.py\", line 118, in receive\n    raise EndOfStream\nanyio.EndOfStream\n\nDuring handling of the above exception, another exception occurred:\n\nTraceback (most recent call last):\n  File \"/usr/local/lib/python3.12/site-packages/starlette/middleware/errors.py\", line 162, in __call__\n    await self.app(scope, receive, _send)\n  File \"/usr/local/lib/python3.12/site-packages/starlette/middleware/base.py\", line 108, in __call__\n    response = await self.dispatch_func(request, call_next)\n               ^^^^^^^^^^^^^^^^^^^^^^^^^^^^^^^^^^^^^^^^^^^^\n  File \"/app/src/main.py\", line 325, in validate_request\n    return await call_next(request)\n           ^^^^^^^^^^^^^^^^^^^^^^^^\n  File \"/usr/local/lib/python3.12/site-packages/starlette/middleware/base.py\", line 84, in call_next\n    raise app_exc\n  File \"/usr/local/lib/python3.12/site-packages/starlette/middleware/base.py\", line 70, in coro\n    await self.app(scope, receive_or_disconnect, send_no_error)\n  File \"/usr/local/lib/python3.12/site-packages/starlette/middleware/base.py\", line 108, in __call__\n    response = await self.dispatch_func(request, call_next)\n               ^^^^^^^^^^^^^^^^^^^^^^^^^^^^^^^^^^^^^^^^^^^^\n  File \"/app/src/main.py\", line 198, in add_security_headers\n    response = await call_next(request)\n               ^^^^^^^^^^^^^^^^^^^^^^^^\n  File \"/usr/local/lib/python3.12/site-packages/starlette/middleware/base.py\", line 84, in call_next\n    raise app_exc\n  File \"/usr/local/lib/python3.12/site-packages/starlette/middleware/base.py\", line 70, in coro\n    await self.app(scope, receive_or_disconnect, send_no_error)\n  File \"/usr/local/lib/python3.12/site-packages/starlette/middleware/base.py\", line 108, in __call__\n    response = await self.dispatch_func(request, call_next)\n               ^^^^^^^^^^^^^^^^^^^^^^^^^^^^^^^^^^^^^^^^^^^^\n  File \"/usr/local/lib/python3.12/site-packages/slowapi/middleware.py\", line 136, in dispatch\n    response = await call_next(request)\n               ^^^^^^^^^^^^^^^^^^^^^^^^\n  File \"/usr/local/lib/python3.12/site-packages/starlette/middleware/base.py\", line 84, in call_next\n    raise app_exc\n  File \"/usr/local/lib/python3.12/site-packages/starlette/middleware/base.py\", line 70, in coro\n    await self.app(scope, receive_or_disconnect, send_no_error)\n  File \"/usr/local/lib/python3.12/site-packages/starlette/middleware/cors.py\", line 83, in __call__\n    await self.app(scope, receive, send)\n  File \"/usr/local/lib/python3.12/site-packages/starlette/middleware/exceptions.py\", line 79, in __call__\n    raise exc\n  File \"/usr/local/lib/python3.12/site-packages/starlette/middleware/exceptions.py\", line 68, in __call__\n    await self.app(scope, receive, sender)\n  File \"/usr/local/lib/python3.12/site-packages/fastapi/middleware/asyncexitstack.py\", line 20, in __call__\n    raise e\n  File \"/usr/local/lib/python3.12/site-packages/fastapi/middleware/asyncexitstack.py\", line 17, in __call__\n    await self.app(scope, receive, send)\n  File \"/usr/local/lib/python3.12/site-packages/starlette/routing.py\", line 718, in __call__\n    await route.handle(scope, receive, send)\n  File \"/usr/local/lib/python3.12/site-packages/starlette/routing.py\", line 276, in handle\n    await self.app(scope, receive, send)\n  File \"/usr/local/lib/python3.12/site-packages/starlette/routing.py\", line 66, in app\n    response = await func(request)\n               ^^^^^^^^^^^^^^^^^^^\n  File \"/usr/local/lib/python3.12/site-packages/fastapi/routing.py\", line 264, in app\n    solved_result = await solve_dependencies(\n                    ^^^^^^^^^^^^^^^^^^^^^^^^^\n  File \"/usr/local/lib/python3.12/site-packages/fastapi/dependencies/utils.py\", line 563, in solve_dependencies\n    solved_result = await solve_dependencies(\n                    ^^^^^^^^^^^^^^^^^^^^^^^^^\n  File \"/usr/local/lib/python3.12/site-packages/fastapi/dependencies/utils.py\", line 588, in solve_dependencies\n    solved = await solve_generator(\n             ^^^^^^^^^^^^^^^^^^^^^^\n  File \"/usr/local/lib/python3.12/site-packages/fastapi/dependencies/utils.py\", line 513, in solve_generator\n    return await stack.enter_async_context(cm)\n           ^^^^^^^^^^^^^^^^^^^^^^^^^^^^^^^^^^^\n  File \"/usr/local/lib/python3.12/contextlib.py\", line 659, in enter_async_context\n    result = await _enter(cm)\n             ^^^^^^^^^^^^^^^^\n  File \"/usr/local/lib/python3.12/contextlib.py\", line 210, in __aenter__\n    return await anext(self.gen)\n           ^^^^^^^^^^^^^^^^^^^^^\n  File \"/app/src/db/database.py\", line 338, in get_db\n    async with db_manager.get_session() as session:\n               ^^^^^^^^^^^^^^^^^^^^^^^^\nTypeError: '_GeneratorContextManager' object does not support the asynchronous context manager protocol", "taskName": "Task-231", "asctime": "2025-10-17 07:00:36,702"}
{"timestamp": "2025-10-17 07:03:22", "level": "ERROR", "logger": "src.main", "message": "Failed to initialize position monitoring worker: '_GeneratorContextManager' object is not an iterator", "taskName": "Task-2", "asctime": "2025-10-17 07:03:22,828"}
{"timestamp": "2025-10-17 07:08:49", "level": "ERROR", "logger": "src.main", "message": "Failed to initialize position monitoring worker: '_GeneratorContextManager' object is not an iterator", "taskName": "Task-2", "asctime": "2025-10-17 07:08:49,641"}
{"timestamp": "2025-10-17 07:09:05", "level": "ERROR", "logger": "src.api.webhooks", "message": "Failed to log webhook event: (sqlalchemy.dialects.postgresql.asyncpg.IntegrityError) <class 'asyncpg.exceptions.ForeignKeyViolationError'>: insert or update on table \"webhook_events\" violates foreign key constraint \"webhook_events_user_address_fkey\"\nDETAIL:  Key (user_address)=() is not present in table \"users\".\n[SQL: INSERT INTO webhook_events (user_address, event_type, payload, processed, created_at) VALUES ($1::VARCHAR, $2::VARCHAR, $3::VARCHAR, $4::BOOLEAN, $5::TIMESTAMP WITHOUT TIME ZONE) RETURNING webhook_events.id]\n[parameters: ('', 'received', '{\"secret\": \"8002009ce1ceda78c1e69308c88af2b085109db7e63fb68cc75bfb7dc4bdf129\", \"symbol\": \"BTC-USD\", \"side\": \"buy\", \"size\": 0.001}', False, datetime.datetime(2025, 10, 17, 7, 9, 5, 824174))]\n(Background on this error at: https://sqlalche.me/e/20/gkpj)", "taskName": "starlette.middleware.base.BaseHTTPMiddleware.__call__.<locals>.call_next.<locals>.coro", "asctime": "2025-10-17 07:09:05,874"}
{"timestamp": "2025-10-17 07:09:05", "level": "ERROR", "logger": "src.api.webhooks", "message": "Failed to log webhook event: This Session's transaction has been rolled back due to a previous exception during flush. To begin a new transaction with this Session, first issue Session.rollback(). Original exception was: (sqlalchemy.dialects.postgresql.asyncpg.IntegrityError) <class 'asyncpg.exceptions.ForeignKeyViolationError'>: insert or update on table \"webhook_events\" violates foreign key constraint \"webhook_events_user_address_fkey\"\nDETAIL:  Key (user_address)=() is not present in table \"users\".\n[SQL: INSERT INTO webhook_events (user_address, event_type, payload, processed, created_at) VALUES ($1::VARCHAR, $2::VARCHAR, $3::VARCHAR, $4::BOOLEAN, $5::TIMESTAMP WITHOUT TIME ZONE) RETURNING webhook_events.id]\n[parameters: ('', 'received', '{\"secret\": \"8002009ce1ceda78c1e69308c88af2b085109db7e63fb68cc75bfb7dc4bdf129\", \"symbol\": \"BTC-USD\", \"side\": \"buy\", \"size\": 0.001}', False, datetime.datetime(2025, 10, 17, 7, 9, 5, 824174))]\n(Background on this error at: https://sqlalche.me/e/20/gkpj) (Background on this error at: https://sqlalche.me/e/20/7s2a)", "taskName": "starlette.middleware.base.BaseHTTPMiddleware.__call__.<locals>.call_next.<locals>.coro", "asctime": "2025-10-17 07:09:05,879"}
{"timestamp": "2025-10-17 07:09:53", "level": "ERROR", "logger": "src.main", "message": "Failed to initialize position monitoring worker: '_GeneratorContextManager' object is not an iterator", "taskName": "Task-2", "asctime": "2025-10-17 07:09:53,187"}
{"timestamp": "2025-10-17 07:10:03", "level": "ERROR", "logger": "src.bot.state_manager", "message": "Failed to get user positions for : 'AsyncSession' object has no attribute 'exec'", "taskName": "starlette.middleware.base.BaseHTTPMiddleware.__call__.<locals>.call_next.<locals>.coro", "asctime": "2025-10-17 07:10:03,140"}
{"timestamp": "2025-10-17 07:10:03", "level": "ERROR", "logger": "src.bot.trading_engine", "message": "Risk check error for : 'price'", "taskName": "starlette.middleware.base.BaseHTTPMiddleware.__call__.<locals>.call_next.<locals>.coro", "asctime": "2025-10-17 07:10:03,140"}
{"timestamp": "2025-10-17 07:10:03", "level": "ERROR", "logger": "src.bot.telegram_manager", "message": "Failed to send Telegram message: Invalid Telegram bot token", "taskName": "starlette.middleware.base.BaseHTTPMiddleware.__call__.<locals>.call_next.<locals>.coro", "asctime": "2025-10-17 07:10:03,141"}
{"timestamp": "2025-10-17 07:10:48", "level": "ERROR", "logger": "src.bot.state_manager", "message": "Failed to get user positions for : 'AsyncSession' object has no attribute 'exec'", "taskName": "starlette.middleware.base.BaseHTTPMiddleware.__call__.<locals>.call_next.<locals>.coro", "asctime": "2025-10-17 07:10:48,578"}
{"timestamp": "2025-10-17 07:10:48", "level": "ERROR", "logger": "src.bot.trading_engine", "message": "Risk check error for : 'price'", "taskName": "starlette.middleware.base.BaseHTTPMiddleware.__call__.<locals>.call_next.<locals>.coro", "asctime": "2025-10-17 07:10:48,578"}
{"timestamp": "2025-10-17 07:10:48", "level": "ERROR", "logger": "src.bot.telegram_manager", "message": "Failed to send Telegram message: Invalid Telegram bot token", "taskName": "starlette.middleware.base.BaseHTTPMiddleware.__call__.<locals>.call_next.<locals>.coro", "asctime": "2025-10-17 07:10:48,579"}
{"timestamp": "2025-10-17 07:14:23", "level": "ERROR", "logger": "src.main", "message": "Failed to initialize position monitoring worker: '_GeneratorContextManager' object is not an iterator", "taskName": "Task-2", "asctime": "2025-10-17 07:14:23,107"}
{"timestamp": "2025-10-17 07:14:56", "level": "ERROR", "logger": "src.bot.state_manager", "message": "Failed to get user positions for : 'AsyncSession' object has no attribute 'exec'", "taskName": "starlette.middleware.base.BaseHTTPMiddleware.__call__.<locals>.call_next.<locals>.coro", "asctime": "2025-10-17 07:14:56,521"}
{"timestamp": "2025-10-17 07:14:56", "level": "ERROR", "logger": "src.bot.trading_engine", "message": "Risk check error for : 'price'", "taskName": "starlette.middleware.base.BaseHTTPMiddleware.__call__.<locals>.call_next.<locals>.coro", "asctime": "2025-10-17 07:14:56,521"}
{"timestamp": "2025-10-17 07:14:56", "level": "ERROR", "logger": "src.bot.telegram_manager", "message": "Failed to send Telegram message: Invalid Telegram bot token", "taskName": "starlette.middleware.base.BaseHTTPMiddleware.__call__.<locals>.call_next.<locals>.coro", "asctime": "2025-10-17 07:14:56,522"}
{"timestamp": "2025-10-17 07:15:35", "level": "ERROR", "logger": "src.main", "message": "Failed to initialize position monitoring worker: '_GeneratorContextManager' object is not an iterator", "taskName": "Task-2", "asctime": "2025-10-17 07:15:35,116"}
{"timestamp": "2025-10-17 07:15:53", "level": "ERROR", "logger": "src.bot.state_manager", "message": "Failed to get user positions for : 'AsyncSession' object has no attribute 'exec'", "taskName": "starlette.middleware.base.BaseHTTPMiddleware.__call__.<locals>.call_next.<locals>.coro", "asctime": "2025-10-17 07:15:53,836"}
{"timestamp": "2025-10-17 07:15:53", "level": "ERROR", "logger": "src.bot.dydx_client", "message": "Failed to create dYdX client: NodeConfig.__init__() missing 1 required positional argument: 'channel'", "taskName": "starlette.middleware.base.BaseHTTPMiddleware.__call__.<locals>.call_next.<locals>.coro", "asctime": "2025-10-17 07:15:53,869"}
{"timestamp": "2025-10-17 07:15:53", "level": "ERROR", "logger": "src.bot.telegram_manager", "message": "Failed to send Telegram message: Invalid Telegram bot token", "taskName": "starlette.middleware.base.BaseHTTPMiddleware.__call__.<locals>.call_next.<locals>.coro", "asctime": "2025-10-17 07:15:53,870"}
{"timestamp": "2025-10-21 09:09:59", "level": "ERROR", "logger": "src.main", "message": "Failed to initialize position monitoring worker: '_GeneratorContextManager' object is not an iterator", "taskName": "Task-2", "asctime": "2025-10-21 09:09:59,032"}
{"timestamp": "2025-10-21 09:37:10", "level": "ERROR", "logger": "src.bot.state_manager", "message": "Failed to get user positions for : 'AsyncSession' object has no attribute 'exec'", "taskName": "starlette.middleware.base.BaseHTTPMiddleware.__call__.<locals>.call_next.<locals>.coro", "asctime": "2025-10-21 09:37:10,993"}
{"timestamp": "2025-10-21 09:37:11", "level": "ERROR", "logger": "src.bot.dydx_client", "message": "Failed to create dYdX client: NodeConfig.__init__() missing 1 required positional argument: 'channel'", "taskName": "starlette.middleware.base.BaseHTTPMiddleware.__call__.<locals>.call_next.<locals>.coro", "asctime": "2025-10-21 09:37:11,007"}
{"timestamp": "2025-10-21 09:37:11", "level": "ERROR", "logger": "src.bot.telegram_manager", "message": "Failed to send Telegram message: Invalid Telegram bot token", "taskName": "starlette.middleware.base.BaseHTTPMiddleware.__call__.<locals>.call_next.<locals>.coro", "asctime": "2025-10-21 09:37:11,008"}
{"timestamp": "2025-10-21 09:43:56", "level": "ERROR", "logger": "src.bot.state_manager", "message": "Failed to get user positions for : 'AsyncSession' object has no attribute 'exec'", "taskName": "starlette.middleware.base.BaseHTTPMiddleware.__call__.<locals>.call_next.<locals>.coro", "asctime": "2025-10-21 09:43:56,208"}
{"timestamp": "2025-10-21 09:43:56", "level": "ERROR", "logger": "src.bot.dydx_client", "message": "Failed to create dYdX client: NodeConfig.__init__() missing 1 required positional argument: 'channel'", "taskName": "starlette.middleware.base.BaseHTTPMiddleware.__call__.<locals>.call_next.<locals>.coro", "asctime": "2025-10-21 09:43:56,220"}
{"timestamp": "2025-10-21 09:43:56", "level": "ERROR", "logger": "src.bot.telegram_manager", "message": "Failed to send Telegram message: Invalid Telegram bot token", "taskName": "starlette.middleware.base.BaseHTTPMiddleware.__call__.<locals>.call_next.<locals>.coro", "asctime": "2025-10-21 09:43:56,221"}
{"timestamp": "2025-10-21 09:51:26", "level": "ERROR", "logger": "src.main", "message": "Failed to initialize position monitoring worker: '_GeneratorContextManager' object is not an iterator", "taskName": "Task-2", "asctime": "2025-10-21 09:51:26,677"}
{"timestamp": "2025-10-21 09:52:00", "level": "ERROR", "logger": "src.bot.state_manager", "message": "Failed to get user positions for : 'AsyncSession' object has no attribute 'exec'", "taskName": "starlette.middleware.base.BaseHTTPMiddleware.__call__.<locals>.call_next.<locals>.coro", "asctime": "2025-10-21 09:52:00,186"}
{"timestamp": "2025-10-21 09:52:00", "level": "ERROR", "logger": "src.bot.dydx_client", "message": "Failed to create dYdX client: NodeClient.__init__() got an unexpected keyword argument 'config'", "taskName": "starlette.middleware.base.BaseHTTPMiddleware.__call__.<locals>.call_next.<locals>.coro", "asctime": "2025-10-21 09:52:00,206"}
{"timestamp": "2025-10-21 09:52:00", "level": "ERROR", "logger": "src.bot.telegram_manager", "message": "Failed to send Telegram message: Invalid Telegram bot token", "taskName": "starlette.middleware.base.BaseHTTPMiddleware.__call__.<locals>.call_next.<locals>.coro", "asctime": "2025-10-21 09:52:00,206"}
{"timestamp": "2025-10-21 09:56:11", "level": "ERROR", "logger": "src.main", "message": "Failed to initialize position monitoring worker: '_GeneratorContextManager' object is not an iterator", "taskName": "Task-2", "asctime": "2025-10-21 09:56:11,345"}
{"timestamp": "2025-10-21 10:27:08", "level": "ERROR", "logger": "src.main", "message": "Failed to initialize position monitoring worker: '_GeneratorContextManager' object is not an iterator", "taskName": "Task-2", "asctime": "2025-10-21 10:27:08,216"}
{"timestamp": "2025-10-21 10:27:33", "level": "ERROR", "logger": "src.bot.state_manager", "message": "Failed to get user positions for : 'AsyncSession' object has no attribute 'exec'", "taskName": "starlette.middleware.base.BaseHTTPMiddleware.__call__.<locals>.call_next.<locals>.coro", "asctime": "2025-10-21 10:27:33,415"}
{"timestamp": "2025-10-21 10:27:33", "level": "ERROR", "logger": "src.bot.telegram_manager", "message": "Failed to send Telegram message: Invalid Telegram bot token", "taskName": "starlette.middleware.base.BaseHTTPMiddleware.__call__.<locals>.call_next.<locals>.coro", "asctime": "2025-10-21 10:27:33,418"}
{"timestamp": "2025-10-21 11:20:01", "level": "ERROR", "logger": "src.main", "message": "Failed to initialize position monitoring worker: '_GeneratorContextManager' object is not an iterator", "taskName": "Task-2", "asctime": "2025-10-21 11:20:01,658"}
{"timestamp": "2025-10-21 11:20:11", "level": "ERROR", "logger": "src.bot.state_manager", "message": "Failed to get user positions for : 'AsyncSession' object has no attribute 'exec'", "taskName": "starlette.middleware.base.BaseHTTPMiddleware.__call__.<locals>.call_next.<locals>.coro", "asctime": "2025-10-21 11:20:11,174"}
{"timestamp": "2025-10-21 11:20:11", "level": "ERROR", "logger": "src.bot.telegram_manager", "message": "Failed to send Telegram message: Invalid Telegram bot token", "taskName": "starlette.middleware.base.BaseHTTPMiddleware.__call__.<locals>.call_next.<locals>.coro", "asctime": "2025-10-21 11:20:11,174"}
{"timestamp": "2025-10-21 11:22:09", "level": "ERROR", "logger": "src.main", "message": "Failed to initialize position monitoring worker: '_GeneratorContextManager' object is not an iterator", "taskName": "Task-2", "asctime": "2025-10-21 11:22:09,191"}
{"timestamp": "2025-10-21 11:22:31", "level": "ERROR", "logger": "src.bot.state_manager", "message": "Failed to get user positions for : 'AsyncSession' object has no attribute 'exec'", "taskName": "starlette.middleware.base.BaseHTTPMiddleware.__call__.<locals>.call_next.<locals>.coro", "asctime": "2025-10-21 11:22:31,625"}
{"timestamp": "2025-10-21 11:22:31", "level": "ERROR", "logger": "src.bot.dydx_client", "message": "Failed to create dYdX client: No module named 'dydx_v4_client.chain'", "taskName": "starlette.middleware.base.BaseHTTPMiddleware.__call__.<locals>.call_next.<locals>.coro", "asctime": "2025-10-21 11:22:31,635"}
{"timestamp": "2025-10-21 11:22:31", "level": "ERROR", "logger": "src.bot.telegram_manager", "message": "Failed to send Telegram message: Invalid Telegram bot token", "taskName": "starlette.middleware.base.BaseHTTPMiddleware.__call__.<locals>.call_next.<locals>.coro", "asctime": "2025-10-21 11:22:31,636"}
{"timestamp": "2025-10-21 11:27:16", "level": "ERROR", "logger": "src.main", "message": "Failed to initialize position monitoring worker: '_GeneratorContextManager' object is not an iterator", "taskName": "Task-2", "asctime": "2025-10-21 11:27:16,910"}
{"timestamp": "2025-10-21 11:27:19", "level": "ERROR", "logger": "src.bot.state_manager", "message": "Failed to get user positions for : 'AsyncSession' object has no attribute 'exec'", "taskName": "starlette.middleware.base.BaseHTTPMiddleware.__call__.<locals>.call_next.<locals>.coro", "asctime": "2025-10-21 11:27:19,057"}
{"timestamp": "2025-10-21 11:27:19", "level": "ERROR", "logger": "src.bot.dydx_client", "message": "Failed to create dYdX client: No module named 'dydx_v4_client.chain'", "taskName": "starlette.middleware.base.BaseHTTPMiddleware.__call__.<locals>.call_next.<locals>.coro", "asctime": "2025-10-21 11:27:19,060"}
{"timestamp": "2025-10-21 11:27:19", "level": "ERROR", "logger": "src.bot.telegram_manager", "message": "Failed to send Telegram message: Invalid Telegram bot token", "taskName": "starlette.middleware.base.BaseHTTPMiddleware.__call__.<locals>.call_next.<locals>.coro", "asctime": "2025-10-21 11:27:19,060"}
{"timestamp": "2025-10-21 11:33:20", "level": "ERROR", "logger": "src.main", "message": "Failed to initialize position monitoring worker: '_GeneratorContextManager' object is not an iterator", "taskName": "Task-2", "asctime": "2025-10-21 11:33:20,015"}
{"timestamp": "2025-10-21 11:34:07", "level": "ERROR", "logger": "src.bot.state_manager", "message": "Failed to get user positions for : 'AsyncSession' object has no attribute 'exec'", "taskName": "starlette.middleware.base.BaseHTTPMiddleware.__call__.<locals>.call_next.<locals>.coro", "asctime": "2025-10-21 11:34:07,392"}
{"timestamp": "2025-10-21 11:34:07", "level": "ERROR", "logger": "src.bot.dydx_client", "message": "Failed to create dYdX client: No module named 'dydx_v4_client.chain'", "taskName": "starlette.middleware.base.BaseHTTPMiddleware.__call__.<locals>.call_next.<locals>.coro", "asctime": "2025-10-21 11:34:07,400"}
{"timestamp": "2025-10-21 11:34:07", "level": "ERROR", "logger": "src.bot.telegram_manager", "message": "Failed to send Telegram message: Invalid Telegram bot token", "taskName": "starlette.middleware.base.BaseHTTPMiddleware.__call__.<locals>.call_next.<locals>.coro", "asctime": "2025-10-21 11:34:07,400"}
{"timestamp": "2025-10-21 13:05:06", "level": "ERROR", "logger": "src.main", "message": "Failed to initialize position monitoring worker: '_GeneratorContextManager' object is not an iterator", "taskName": "Task-2", "asctime": "2025-10-21 13:05:06,430"}
{"timestamp": "2025-10-21 13:05:10", "level": "ERROR", "logger": "src.bot.state_manager", "message": "Failed to get user positions for : 'AsyncSession' object has no attribute 'exec'", "taskName": "starlette.middleware.base.BaseHTTPMiddleware.__call__.<locals>.call_next.<locals>.coro", "asctime": "2025-10-21 13:05:10,879"}
{"timestamp": "2025-10-21 13:05:10", "level": "ERROR", "logger": "src.bot.dydx_client", "message": "Failed to create dYdX client: No module named 'dydx_v4_client.chain'", "taskName": "starlette.middleware.base.BaseHTTPMiddleware.__call__.<locals>.call_next.<locals>.coro", "asctime": "2025-10-21 13:05:10,883"}
{"timestamp": "2025-10-21 13:05:10", "level": "ERROR", "logger": "src.bot.telegram_manager", "message": "Failed to send Telegram message: Invalid Telegram bot token", "taskName": "starlette.middleware.base.BaseHTTPMiddleware.__call__.<locals>.call_next.<locals>.coro", "asctime": "2025-10-21 13:05:10,883"}
{"timestamp": "2025-10-22 11:20:42", "level": "ERROR", "logger": "src.main", "message": "Failed to initialize position monitoring worker: '_GeneratorContextManager' object is not an iterator", "taskName": "Task-2", "asctime": "2025-10-22 11:20:42,342"}
{"timestamp": "2025-10-24 13:43:22", "level": "ERROR", "logger": "src.main", "message": "Failed to initialize position monitoring worker: '_GeneratorContextManager' object is not an iterator", "taskName": "Task-2", "asctime": "2025-10-24 13:43:22,554"}
{"timestamp": "2025-10-24 13:54:54", "level": "ERROR", "logger": "src.main", "message": "Failed to initialize position monitoring worker: '_GeneratorContextManager' object is not an iterator", "taskName": "Task-2", "asctime": "2025-10-24 13:54:54,919"}
{"timestamp": "2025-10-24 14:11:20", "level": "ERROR", "logger": "src.api.user", "message": "Failed to initialize dYdX client or fetch balance for user 0xfe09335d5d71431fef3d53beddc772c8269bf953: The use of the Mnemonic features of Account is disabled by default until its API stabilizes. To use these features, please enable them by running `Account.enable_unaudited_hdwallet_features()` and try again.", "taskName": "starlette.middleware.base.BaseHTTPMiddleware.__call__.<locals>.call_next.<locals>.coro", "asctime": "2025-10-24 14:11:20,791"}
{"timestamp": "2025-10-24 14:11:32", "level": "ERROR", "logger": "src.api.user", "message": "Failed to initialize dYdX client or fetch balance for user 0xfe09335d5d71431fef3d53beddc772c8269bf953: The use of the Mnemonic features of Account is disabled by default until its API stabilizes. To use these features, please enable them by running `Account.enable_unaudited_hdwallet_features()` and try again.", "taskName": "starlette.middleware.base.BaseHTTPMiddleware.__call__.<locals>.call_next.<locals>.coro", "asctime": "2025-10-24 14:11:32,317"}
{"timestamp": "2025-10-24 14:23:14", "level": "ERROR", "logger": "src.api.user", "message": "Failed to initialize dYdX client or fetch balance for user 0xfe09335d5d71431fef3d53beddc772c8269bf953: The use of the Mnemonic features of Account is disabled by default until its API stabilizes. To use these features, please enable them by running `Account.enable_unaudited_hdwallet_features()` and try again.", "taskName": "starlette.middleware.base.BaseHTTPMiddleware.__call__.<locals>.call_next.<locals>.coro", "asctime": "2025-10-24 14:23:14,474"}
{"timestamp": "2025-10-24 14:26:34", "level": "ERROR", "logger": "src.api.user", "message": "Failed to initialize dYdX client or fetch balance for user 0xfe09335d5d71431fef3d53beddc772c8269bf953: The use of the Mnemonic features of Account is disabled by default until its API stabilizes. To use these features, please enable them by running `Account.enable_unaudited_hdwallet_features()` and try again.", "taskName": "starlette.middleware.base.BaseHTTPMiddleware.__call__.<locals>.call_next.<locals>.coro", "asctime": "2025-10-24 14:26:34,003"}
{"timestamp": "2025-10-24 14:30:40", "level": "ERROR", "logger": "src.main", "message": "Failed to initialize position monitoring worker: '_GeneratorContextManager' object is not an iterator", "taskName": "Task-2", "asctime": "2025-10-24 14:30:40,865"}
{"timestamp": "2025-10-24 14:32:05", "level": "ERROR", "logger": "src.api.user", "message": "Failed to initialize dYdX client or fetch balance for user 0xfe09335d5d71431fef3d53beddc772c8269bf953: The use of the Mnemonic features of Account is disabled by default until its API stabilizes. To use these features, please enable them by running `Account.enable_unaudited_hdwallet_features()` and try again.", "taskName": "starlette.middleware.base.BaseHTTPMiddleware.__call__.<locals>.call_next.<locals>.coro", "asctime": "2025-10-24 14:32:05,989"}
{"timestamp": "2025-10-24 14:37:26", "level": "ERROR", "logger": "src.main", "message": "Failed to initialize position monitoring worker: '_GeneratorContextManager' object is not an iterator", "taskName": "Task-2", "asctime": "2025-10-24 14:37:26,494"}
{"timestamp": "2025-10-24 14:37:49", "level": "ERROR", "logger": "src.api.user", "message": "Failed to initialize dYdX client or fetch balance for user 0xfe09335d5d71431fef3d53beddc772c8269bf953: The use of the Mnemonic features of Account is disabled by default until its API stabilizes. To use these features, please enable them by running `Account.enable_unaudited_hdwallet_features()` and try again.", "taskName": "starlette.middleware.base.BaseHTTPMiddleware.__call__.<locals>.call_next.<locals>.coro", "asctime": "2025-10-24 14:37:49,378"}
{"timestamp": "2025-10-24 14:39:27", "level": "ERROR", "logger": "src.api.user", "message": "Failed to initialize dYdX client or fetch balance for user 0xfe09335d5d71431fef3d53beddc772c8269bf953: The use of the Mnemonic features of Account is disabled by default until its API stabilizes. To use these features, please enable them by running `Account.enable_unaudited_hdwallet_features()` and try again.", "taskName": "starlette.middleware.base.BaseHTTPMiddleware.__call__.<locals>.call_next.<locals>.coro", "asctime": "2025-10-24 14:39:27,507"}
{"timestamp": "2025-10-24 14:41:54", "level": "ERROR", "logger": "src.api.user", "message": "Failed to initialize dYdX client or fetch balance for user 0xfe09335d5d71431fef3d53beddc772c8269bf953: The use of the Mnemonic features of Account is disabled by default until its API stabilizes. To use these features, please enable them by running `Account.enable_unaudited_hdwallet_features()` and try again.", "taskName": "starlette.middleware.base.BaseHTTPMiddleware.__call__.<locals>.call_next.<locals>.coro", "asctime": "2025-10-24 14:41:54,023"}
{"timestamp": "2025-10-24 14:42:23", "level": "ERROR", "logger": "src.main", "message": "Failed to initialize position monitoring worker: '_GeneratorContextManager' object is not an iterator", "taskName": "Task-2", "asctime": "2025-10-24 14:42:23,364"}
{"timestamp": "2025-10-24 14:42:52", "level": "ERROR", "logger": "src.api.user", "message": "Failed to initialize dYdX client or fetch balance for user 0xfe09335d5d71431fef3d53beddc772c8269bf953: The use of the Mnemonic features of Account is disabled by default until its API stabilizes. To use these features, please enable them by running `Account.enable_unaudited_hdwallet_features()` and try again.", "taskName": "starlette.middleware.base.BaseHTTPMiddleware.__call__.<locals>.call_next.<locals>.coro", "asctime": "2025-10-24 14:42:52,584"}
{"timestamp": "2025-10-24 14:43:06", "level": "ERROR", "logger": "src.api.user", "message": "Failed to initialize dYdX client or fetch balance for user 0xfe09335d5d71431fef3d53beddc772c8269bf953: The use of the Mnemonic features of Account is disabled by default until its API stabilizes. To use these features, please enable them by running `Account.enable_unaudited_hdwallet_features()` and try again.", "taskName": "starlette.middleware.base.BaseHTTPMiddleware.__call__.<locals>.call_next.<locals>.coro", "asctime": "2025-10-24 14:43:06,645"}
{"timestamp": "2025-10-24 14:45:58", "level": "ERROR", "logger": "src.main", "message": "Failed to initialize position monitoring worker: '_GeneratorContextManager' object is not an iterator", "taskName": "Task-2", "asctime": "2025-10-24 14:45:58,305"}
{"timestamp": "2025-10-24 14:46:28", "level": "ERROR", "logger": "src.api.user", "message": "Failed to initialize dYdX client or fetch balance for user 0xfe09335d5d71431fef3d53beddc772c8269bf953: The use of the Mnemonic features of Account is disabled by default until its API stabilizes. To use these features, please enable them by running `Account.enable_unaudited_hdwallet_features()` and try again.", "taskName": "starlette.middleware.base.BaseHTTPMiddleware.__call__.<locals>.call_next.<locals>.coro", "asctime": "2025-10-24 14:46:28,659"}
{"timestamp": "2025-10-24 14:46:42", "level": "ERROR", "logger": "src.api.user", "message": "Failed to initialize dYdX client or fetch balance for user 0xfe09335d5d71431fef3d53beddc772c8269bf953: The use of the Mnemonic features of Account is disabled by default until its API stabilizes. To use these features, please enable them by running `Account.enable_unaudited_hdwallet_features()` and try again.", "taskName": "starlette.middleware.base.BaseHTTPMiddleware.__call__.<locals>.call_next.<locals>.coro", "asctime": "2025-10-24 14:46:42,969"}
{"timestamp": "2025-10-24 14:48:24", "level": "ERROR", "logger": "src.main", "message": "Failed to initialize position monitoring worker: '_GeneratorContextManager' object is not an iterator", "taskName": "Task-2", "asctime": "2025-10-24 14:48:24,363"}
{"timestamp": "2025-10-24 14:49:01", "level": "ERROR", "logger": "src.api.user", "message": "Failed to initialize dYdX client or fetch balance for user 0xfe09335d5d71431fef3d53beddc772c8269bf953: The use of the Mnemonic features of Account is disabled by default until its API stabilizes. To use these features, please enable them by running `Account.enable_unaudited_hdwallet_features()` and try again.", "taskName": "starlette.middleware.base.BaseHTTPMiddleware.__call__.<locals>.call_next.<locals>.coro", "asctime": "2025-10-24 14:49:01,256"}
{"timestamp": "2025-10-24 14:49:11", "level": "ERROR", "logger": "src.api.user", "message": "Failed to initialize dYdX client or fetch balance for user 0xfe09335d5d71431fef3d53beddc772c8269bf953: The use of the Mnemonic features of Account is disabled by default until its API stabilizes. To use these features, please enable them by running `Account.enable_unaudited_hdwallet_features()` and try again.", "taskName": "starlette.middleware.base.BaseHTTPMiddleware.__call__.<locals>.call_next.<locals>.coro", "asctime": "2025-10-24 14:49:11,647"}
{"timestamp": "2025-10-24 14:50:27", "level": "ERROR", "logger": "src.main", "message": "Failed to initialize position monitoring worker: '_GeneratorContextManager' object is not an iterator", "taskName": "Task-2", "asctime": "2025-10-24 14:50:27,990"}
{"timestamp": "2025-10-24 14:51:34", "level": "ERROR", "logger": "src.api.user", "message": "Failed to initialize dYdX client or fetch balance for user 0xfe09335d5d71431fef3d53beddc772c8269bf953: The use of the Mnemonic features of Account is disabled by default until its API stabilizes. To use these features, please enable them by running `Account.enable_unaudited_hdwallet_features()` and try again.", "taskName": "starlette.middleware.base.BaseHTTPMiddleware.__call__.<locals>.call_next.<locals>.coro", "asctime": "2025-10-24 14:51:34,964"}
{"timestamp": "2025-10-24 15:04:33", "level": "ERROR", "logger": "src.api.user", "message": "Failed to initialize dYdX client or fetch balance for user 0xfe09335d5d71431fef3d53beddc772c8269bf953: The use of the Mnemonic features of Account is disabled by default until its API stabilizes. To use these features, please enable them by running `Account.enable_unaudited_hdwallet_features()` and try again.", "taskName": "starlette.middleware.base.BaseHTTPMiddleware.__call__.<locals>.call_next.<locals>.coro", "asctime": "2025-10-24 15:04:33,538"}
{"timestamp": "2025-10-24 15:09:27", "level": "ERROR", "logger": "src.api.user", "message": "Failed to initialize dYdX client or fetch balance for user 0xfe09335d5d71431fef3d53beddc772c8269bf953: The use of the Mnemonic features of Account is disabled by default until its API stabilizes. To use these features, please enable them by running `Account.enable_unaudited_hdwallet_features()` and try again.", "taskName": "starlette.middleware.base.BaseHTTPMiddleware.__call__.<locals>.call_next.<locals>.coro", "asctime": "2025-10-24 15:09:27,709"}
